Workbook

Sheet 1
A1: 2025-11-05 - Wednesday
A2: Recs:
A3: NVDA – NVIDIA Corporation
A4: AAPL – Apple Inc.
A5: MSFT – Microsoft Corporation
A6: ERICb.ST – Telefonaktiebolaget LM Ericsson B
A7: BOL – The Boliden Company
A8: Perf (prev recs):
A9: N/A
A10: N/A
A11: N/A
A12: N/A
... A529: S&P500 N/A

Sheet 2
A1: 2025-11-19 - Wednesday
A2: Recs:
A3: NVDA – NVIDIA Corp
A4: ERIC – Telefonaktiebolaget LM Ericsson
A5: VOLV-B.ST – AB Volvo (publ) B
A6: AZN.ST – AstraZeneca PLC
A7: VOLCAR-B.ST – Volvo Car AB (publ.)
A8: Perf (prev recs):
A9: N/A
A10: N/A
A11: N/A
A12: N/A
... A113: This automation has been paused due to too many unread executions. You can resume it in automations settings or by asking ChatGPT.

Sheet 3
A1: Recs:
A2: GEV - GE Vernova Inc (breakout after strong catalyst and technical momentum)Investors+1
A3: PLTR - Palantir Technologies (recent contract win and positive flow)Barron's
A4: SATS - EchoStar Corp (premarket strength and sector interest)Barron's
A5: AVTR - Avantor Inc (premarket gains signaling momentum)Barron's
A6: FSLR - First Solar (sector news on project supply momentum)Simply Wall St
A8: Prev days return S&P500 +0.67%investing.com
A10: 2025‑12‑12 / 08:15 - Friday
A12: Recs:
A13: NVDA - Nvidia (momentum from AI demand and trading strength)
A14: MSFT - Microsoft (strong cloud earnings sentiment driving flow)
A15: TSLA - Tesla (price breakout and volume spike)
... A52: Prev days return S&P500 -1.07

Sheet Sum and Cleaner
A1: String | B1: Is date? | C1: Date | D1: Rec 1 | E1: Rec 2 | F1: Rec 3 | G1: Rec 4 | H1: Rec 5
A2: 2025-11-05 - Wednesday | B2: =ISNUMBER(LEFT(A2,4)+1-1) -> TRUE | C2: =IF(B2,LEFT(A2,10),C1) -> 2025-11-05 | D2: =A4 -> NVDA – NVIDIA Corporation | E2: =A5 -> AAPL – Apple Inc. | F2: =A6 -> MSFT – Microsoft Corporation | G2: =A7 -> ERICb.ST – Telefonaktiebolaget LM Ericsson B | H2: =A8 -> BOL – The Boliden Company
A3: Recs: | B3: =ISNUMBER(LEFT(A3,4)+1-1) -> FALSE | C3: =IF(B3,LEFT(A3,10),C2) -> 2025-11-05 | D3: =A5 -> AAPL – Apple Inc. | E3: =A6 -> MSFT – Microsoft Corporation | F3: =A7 -> ERICb.ST – Telefonaktiebolaget LM Ericsson B | G3: =A8 -> BOL – The Boliden Company | H3: =A9 -> Perf (prev recs):
A4: NVDA – NVIDIA Corporation | B4: =ISNUMBER(LEFT(A4,4)+1-1) -> FALSE | C4: =IF(B4,LEFT(A4,10),C3) -> 2025-11-05 | D4: =A6 -> MSFT – Microsoft Corporation | E4: =A7 -> ERICb.ST – Telefonaktiebolaget LM Ericsson B | F4: =A8 -> BOL – The Boliden Company | G4: =A9 -> Perf (prev recs): | H4: =A10 -> N/A
A5: AAPL – Apple Inc. | B5: =ISNUMBER(LEFT(A5,4)+1-1) -> FALSE | C5: =IF(B5,LEFT(A5,10),C4) -> 2025-11-05 | D5: =A7 -> ERICb.ST – Telefonaktiebolaget LM Ericsson B | E5: =A8 -> BOL – The Boliden Company | F5: =A9 -> Perf (prev recs): | G5: =A10 -> N/A | H5: =A11 -> N/A
A6: MSFT – Microsoft Corporation | B6: =ISNUMBER(LEFT(A6,4)+1-1) -> FALSE | C6: =IF(B6,LEFT(A6,10),C5) -> 2025-11-05 | D6: =A8 -> BOL – The Boliden Company | E6: =A9 -> Perf (prev recs): | F6: =A10 -> N/A | G6: =A11 -> N/A | H6: =A12 -> N/A
A7: ERICb.ST – Telefonaktiebolaget LM Ericsson B | B7: =ISNUMBER(LEFT(A7,4)+1-1) -> FALSE | C7: =IF(B7,LEFT(A7,10),C6) -> 2025-11-05 | D7: =A9 -> Perf (prev recs): | E7: =A10 -> N/A | F7: =A11 -> N/A | G7: =A12 -> N/A | H7: =A13 -> N/A
A8: BOL – The Boliden Company | B8: =ISNUMBER(LEFT(A8,4)+1-1) -> FALSE | C8: =IF(B8,LEFT(A8,10),C7) -> 2025-11-05 | D8: =A10 -> N/A | E8: =A11 -> N/A | F8: =A12 -> N/A | G8: =A13 -> N/A | H8: =A14 -> N/A
A9: Perf (prev recs): | B9: =ISNUMBER(LEFT(A9,4)+1-1) -> FALSE | C9: =IF(B9,LEFT(A9,10),C8) -> 2025-11-05 | D9: =A11 -> N/A | E9: =A12 -> N/A | F9: =A13 -> N/A | G9: =A14 -> N/A | H9: =A15 -> Avg N/A
A10: N/A | B10: =ISNUMBER(LEFT(A10,4)+1-1) -> FALSE | C10: =IF(B10,LEFT(A10,10),C9) -> 2025-11-05 | D10: =A12 -> N/A | E10: =A13 -> N/A | F10: =A14 -> N/A | G10: =A15 -> Avg N/A | H10: =A16 -> S&P500 +X.XX%
A11: N/A | B11: =ISNUMBER(LEFT(A11,4)+1-1) -> FALSE | C11: =IF(B11,LEFT(A11,10),C10) -> 2025-11-05 | D11: =A13 -> N/A | E11: =A14 -> N/A | F11: =A15 -> Avg N/A | G11: =A16 -> S&P500 +X.XX% | H11: =A17 -> 0
A12: N/A | B12: =ISNUMBER(LEFT(A12,4)+1-1) -> FALSE | C12: =IF(B12,LEFT(A12,10),C11) -> 2025-11-05 | D12: =A14 -> N/A | E12: =A15 -> Avg N/A | F12: =A16 -> S&P500 +X.XX% | G12: =A17 -> 0 | H12: =A18 -> 2025-11-06 - Thursday
A13: N/A | B13: =ISNUMBER(LEFT(A13,4)+1-1) -> FALSE | C13: =IF(B13,LEFT(A13,10),C12) -> 2025-11-05 | D13: =A15 -> Avg N/A | E13: =A16 -> S&P500 +X.XX% | F13: =A17 -> 0 | G13: =A18 -> 2025-11-06 - Thursday | H13: =A19 -> Recs:
... A16: S&P500 +X.XX% | B16: =ISNUMBER(LEFT(A16,4)+1-1) -> FALSE | C16: =IF(B16,LEFT(A16,10),C15) -> 2025-11-05 | D16: =A18 -> 2025-11-06 - Thursday | E16: =A19 -> Recs: | F16: =A20 -> SECU-B.ST – Securitas AB | G16: =A21 -> ERIC-B.ST – Ericsson B | H16: =A22 -> TELIA.ST – Telia Company
B17: =ISNUMBER(LEFT(A17,4)+1-1) -> FALSE | C17: =IF(B17,LEFT(A17,10),C16) -> 2025-11-05 | D17: =A19 -> Recs: | E17: =A20 -> SECU-B.ST – Securitas AB | F17: =A21 -> ERIC-B.ST – Ericsson B | G17: =A22 -> TELIA.ST – Telia Company | H17: =A23 -> SAAB-B.ST – Saab AB
A18: 2025-11-06 - Thursday | B18: =ISNUMBER(LEFT(A18,4)+1-1) -> TRUE | C18: =IF(B18,LEFT(A18,10),C17) -> 2025-11-06 | D18: =A20 -> SECU-B.ST – Securitas AB | E18: =A21 -> ERIC-B.ST – Ericsson B | F18: =A22 -> TELIA.ST – Telia Company | G18: =A23 -> SAAB-B.ST – Saab AB | H18: =A24 -> VOLV-B.ST – AB Volvo B
A19: Recs: | B19: =ISNUMBER(LEFT(A19,4)+1-1) -> FALSE | C19: =IF(B19,LEFT(A19,10),C18) -> 2025-11-06 | D19: =A21 -> ERIC-B.ST – Ericsson B | E19: =A22 -> TELIA.ST – Telia Company | F19: =A23 -> SAAB-B.ST – Saab AB | G19: =A24 -> VOLV-B.ST – AB Volvo B | H19: =A25 -> Perf (prev recs):
A20: SECU-B.ST – Securitas AB | B20: =ISNUMBER(LEFT(A20,4)+1-1) -> FALSE | C20: =IF(B20,LEFT(A20,10),C19) -> 2025-11-06 | D20: =A22 -> TELIA.ST – Telia Company | E20: =A23 -> SAAB-B.ST – Saab AB | F20: =A24 -> VOLV-B.ST – AB Volvo B | G20: =A25 -> Perf (prev recs): | H20: =A26 -> N/A
A21: ERIC-B.ST – Ericsson B | B21: =ISNUMBER(LEFT(A21,4)+1-1) -> FALSE | C21: =IF(B21,LEFT(A21,10),C20) -> 2025-11-06 | D21: =A23 -> SAAB-B.ST – Saab AB | E21: =A24 -> VOLV-B.ST – AB Volvo B | F21: =A25 -> Perf (prev recs): | G21: =A26 -> N/A | H21: =A27 -> 0
A22: TELIA.ST – Telia Company | B22: =ISNUMBER(LEFT(A22,4)+1-1) -> FALSE | C22: =IF(B22,LEFT(A22,10),C21) -> 2025-11-06 | D22: =A24 -> VOLV-B.ST – AB Volvo B | E22: =A25 -> Perf (prev recs): | F22: =A26 -> N/A | G22: =A27 -> 0 | H22: =A28 -> 2025-11-07 - Friday
A23: SAAB-B.ST – Saab AB | B23: =ISNUMBER(LEFT(A23,4)+1-1) -> FALSE | C23: =IF(B23,LEFT(A23,10),C22) -> 2025-11-06 | D23: =A25 -> Perf (prev recs): | E23: =A26 -> N/A | F23: =A27 -> 0 | G23: =A28 -> 2025-11-07 - Friday | H23: =A29 -> Recs:
A24: VOLV-B.ST – AB Volvo B | B24: =ISNUMBER(LEFT(A24,4)+1-1) -> FALSE | C24: =IF(B24,LEFT(A24,10),C23) -> 2025-11-06 | D24: =A26 -> N/A | E24: =A27 -> 0 | F24: =A28 -> 2025-11-07 - Friday | G24: =A29 -> Recs: | H24: =A30 -> TELIA.ST – Telia Company
A25: Perf (prev recs): | B25: =ISNUMBER(LEFT(A25,4)+1-1) -> FALSE | C25: =IF(B25,LEFT(A25,10),C24) -> 2025-11-06 | D25: =A27 -> 0 | E25: =A28 -> 2025-11-07 - Friday | F25: =A29 -> Recs: | G25: =A30 -> TELIA.ST – Telia Company | H25: =A31 -> ERIC-B.ST – Ericsson B
A26: N/A | B26: =ISNUMBER(LEFT(A26,4)+1-1) -> FALSE | C26: =IF(B26,LEFT(A26,10),C25) -> 2025-11-06 | D26: =A28 -> 2025-11-07 - Friday | E26: =A29 -> Recs: | F26: =A30 -> TELIA.ST – Telia Company | G26: =A31 -> ERIC-B.ST – Ericsson B | H26: =A32 -> SAAB-B.ST – Saab AB
B27: =ISNUMBER(LEFT(A27,4)+1-1) -> FALSE | C27: =IF(B27,LEFT(A27,10),C26) -> 2025-11-06 | D27: =A29 -> Recs: | E27: =A30 -> TELIA.ST – Telia Company | F27: =A31 -> ERIC-B.ST – Ericsson B | G27: =A32 -> SAAB-B.ST – Saab AB | H27: =A33 -> VOLV-B.ST – AB Volvo B
A28: 2025-11-07 - Friday | B28: =ISNUMBER(LEFT(A28,4)+1-1) -> TRUE | C28: =IF(B28,LEFT(A28,10),C27) -> 2025-11-07 | D28: =A30 -> TELIA.ST – Telia Company | E28: =A31 -> ERIC-B.ST – Ericsson B | F28: =A32 -> SAAB-B.ST – Saab AB | G28: =A33 -> VOLV-B.ST – AB Volvo B | H28: =A34 -> NOK – Nokia Corporation
A29: Recs: | B29: =ISNUMBER(LEFT(A29,4)+1-1) -> FALSE | C29: =IF(B29,LEFT(A29,10),C28) -> 2025-11-07 | D29: =A31 -> ERIC-B.ST – Ericsson B | E29: =A32 -> SAAB-B.ST – Saab AB | F29: =A33 -> VOLV-B.ST – AB Volvo B | G29: =A34 -> NOK – Nokia Corporation | H29: =A35 -> Perf (prev recs):
A30: TELIA.ST – Telia Company | B30: =ISNUMBER(LEFT(A30,4)+1-1) -> FALSE | C30: =IF(B30,LEFT(A30,10),C29) -> 2025-11-07 | D30: =A32 -> SAAB-B.ST – Saab AB | E30: =A33 -> VOLV-B.ST – AB Volvo B | F30: =A34 -> NOK – Nokia Corporation | G30: =A35 -> Perf (prev recs): | H30: =A36 -> SECU-B.ST N/A
A31: ERIC-B.ST – Ericsson B | B31: =ISNUMBER(LEFT(A31,4)+1-1) -> FALSE | C31: =IF(B31,LEFT(A31,10),C30) -> 2025-11-07 | D31: =A33 -> VOLV-B.ST – AB Volvo B | E31: =A34 -> NOK – Nokia Corporation | F31: =A35 -> Perf (prev recs): | G31: =A36 -> SECU-B.ST N/A | H31: =A37 -> TELIA.ST N/A
A32: SAAB-B.ST – Saab AB | B32: =ISNUMBER(LEFT(A32,4)+1-1) -> FALSE | C32: =IF(B32,LEFT(A32,10),C31) -> 2025-11-07 | D32: =A34 -> NOK – Nokia Corporation | E32: =A35 -> Perf (prev recs): | F32: =A36 -> SECU-B.ST N/A | G32: =A37 -> TELIA.ST N/A | H32: =A38 -> SAAB-B.ST N/A
A33: VOLV-B.ST – AB Volvo B | B33: =ISNUMBER(LEFT(A33,4)+1-1) -> FALSE | C33: =IF(B33,LEFT(A33,10),C32) -> 2025-11-07 | D33: =A35 -> Perf (prev recs): | E33: =A36 -> SECU-B.ST N/A | F33: =A37 -> TELIA.ST N/A | G33: =A38 -> SAAB-B.ST N/A | H33: =A39 -> VOLV-B.ST N/A
A34: NOK – Nokia Corporation | B34: =ISNUMBER(LEFT(A34,4)+1-1) -> FALSE | C34: =IF(B34,LEFT(A34,10),C33) -> 2025-11-07 | D34: =A36 -> SECU-B.ST N/A | E34: =A37 -> TELIA.ST N/A | F34: =A38 -> SAAB-B.ST N/A | G34: =A39 -> VOLV-B.ST N/A | H34: =A40 -> ERIC-B.ST N/A
A35: Perf (prev recs): | B35: =ISNUMBER(LEFT(A35,4)+1-1) -> FALSE | C35: =IF(B35,LEFT(A35,10),C34) -> 2025-11-07 | D35: =A37 -> TELIA.ST N/A | E35: =A38 -> SAAB-B.ST N/A | F35: =A39 -> VOLV-B.ST N/A | G35: =A40 -> ERIC-B.ST N/A | H35: =A41 -> Avg N/A
A36: SECU-B.ST N/A | B36: =ISNUMBER(LEFT(A36,4)+1-1) -> FALSE | C36: =IF(B36,LEFT(A36,10),C35) -> 2025-11-07 | D36: =A38 -> SAAB-B.ST N/A | E36: =A39 -> VOLV-B.ST N/A | F36: =A40 -> ERIC-B.ST N/A | G36: =A41 -> Avg N/A | H36: =A42 -> S&P500 N/A
A37: TELIA.ST N/A | B37: =ISNUMBER(LEFT(A37,4)+1-1) -> FALSE | C37: =IF(B37,LEFT(A37,10),C36) -> 2025-11-07 | D37: =A39 -> VOLV-B.ST N/A | E37: =A40 -> ERIC-B.ST N/A | F37: =A41 -> Avg N/A | G37: =A42 -> S&P500 N/A | H37: =A43 -> 0
A38: SAAB-B.ST N/A | B38: =ISNUMBER(LEFT(A38,4)+1-1) -> FALSE | C38: =IF(B38,LEFT(A38,10),C37) -> 2025-11-07 | D38: =A40 -> ERIC-B.ST N/A | E38: =A41 -> Avg N/A | F38: =A42 -> S&P500 N/A | G38: =A43 -> 0 | H38: =A44 -> 2025-11-08 - Saturday
A39: VOLV-B.ST N/A | B39: =ISNUMBER(LEFT(A39,4)+1-1) -> FALSE | C39: =IF(B39,LEFT(A39,10),C38) -> 2025-11-07 | D39: =A41 -> Avg N/A | E39: =A42 -> S&P500 N/A | F39: =A43 -> 0 | G39: =A44 -> 2025-11-08 - Saturday | H39: =A45 -> Recs:
... A42: S&P500 N/A | B42: =ISNUMBER(LEFT(A42,4)+1-1) -> FALSE | C42: =IF(B42,LEFT(A42,10),C41) -> 2025-11-07 | D42: =A44 -> 2025-11-08 - Saturday | E42: =A45 -> Recs: | F42: =A46 -> SWEC-B.ST – Sweco AB | G42: =A47 -> ATCO-A.ST – Atlas Copco A | H42: =A48 -> HEXA-B.ST – Hexagon AB
B43: =ISNUMBER(LEFT(A43,4)+1-1) -> FALSE | C43: =IF(B43,LEFT(A43,10),C42) -> 2025-11-07 | D43: =A45 -> Recs: | E43: =A46 -> SWEC-B.ST – Sweco AB | F43: =A47 -> ATCO-A.ST – Atlas Copco A | G43: =A48 -> HEXA-B.ST – Hexagon AB | H43: =A49 -> INVE-B.ST – Investor AB
A44: 2025-11-08 - Saturday | B44: =ISNUMBER(LEFT(A44,4)+1-1) -> TRUE | C44: =IF(B44,LEFT(A44,10),C43) -> 2025-11-08 | D44: =A46 -> SWEC-B.ST – Sweco AB | E44: =A47 -> ATCO-A.ST – Atlas Copco A | F44: =A48 -> HEXA-B.ST – Hexagon AB | G44: =A49 -> INVE-B.ST – Investor AB | H44: =A50 -> SAND.ST – Sandvik AB
...

Sheet Clean
A1: String | B1: Rec 1 | C1: Rec 2 | D1: Rec 3 | E1: Rec 4 | F1: Rec 5
A2: ='Sum and Cleaner'!$A$2 -> 2025-11-05 - Wednesday | B2: NVDA – NVIDIA Corporation | C2: AAPL – Apple Inc. | D2: MSFT – Microsoft Corporation | E2: ERICb.ST – Telefonaktiebolaget LM Ericsson B | F2: BOL – The Boliden Company
A3: ='Sum and Cleaner'!$A$18 -> 2025-11-06 - Thursday | B3: SECU-B.ST – Securitas AB | C3: ERIC-B.ST – Ericsson B | D3: TELIA.ST – Telia Company | E3: SAAB-B.ST – Saab AB | F3: VOLV-B.ST – AB Volvo B
A4: ='Sum and Cleaner'!$A$28 -> 2025-11-07 - Friday | B4: TELIA.ST – Telia Company | C4: ERIC-B.ST – Ericsson B | D4: SAAB-B.ST – Saab AB | E4: VOLV-B.ST – AB Volvo B | F4: NOK – Nokia Corporation
A5: ='Sum and Cleaner'!$A$44 -> 2025-11-08 - Saturday | B5: SWEC-B.ST – Sweco AB | C5: ATCO-A.ST – Atlas Copco A | D5: HEXA-B.ST – Hexagon AB | E5: INVE-B.ST – Investor AB | F5: SAND.ST – Sandvik AB
A6: ='Sum and Cleaner'!$A$60 -> 2025-11-09 - Sunday | B6: SWEC-B.ST – Sweco AB | C6: ERIC-B.ST – Ericsson AB B | D6: SSAB-B.ST – SSAB AB B | E6: SHBa.ST – Handelsbanken AB | F6: INVE-B.ST – Investor AB B
A7: ='Sum and Cleaner'!$A$76 -> 2025-11-10 - Monday | B7: HEXA‑B.ST – Hexagon AB | C7: AZN – AstraZeneca plc | D7: EQTAB.ST – EQT AB | E7: SAABb.ST – Saab AB B | F7: BOL.ST – Boliden AB B
A8: ='Sum and Cleaner'!$A$91 -> 2025-10-23 - Thursday | B8: TSLA – Tesla Inc | C8: IBM – International Business Machines Corp | D8: NKE – Nike Inc | E8: SAND – Sandstorm Gold Ltd | F8: SEB_A – SEB AB
A9: ='Sum and Cleaner'!$A$107 -> 2025-10-24 - Friday | B9: TELIA – Telia Company AB | C9: PCELL – PowerCell Sweden AB | D9: SEB_A – SEB AB | E9: ERIC – Ericsson AB | F9: VOLV B – Volvo AB
A10: ='Sum and Cleaner'!$A$123 -> 2025-10-25 - Saturday | B10: AMD – Advanced Micro Devices Inc. | C10: MSFT – Microsoft Corp. | D10: SAND – Sandstorm Gold Ltd. | E10: ERIC – Ericsson AB | F10: TELIA – Telia Company AB
A11: ='Sum and Cleaner'!$A$139 -> 2025-10-26 - Sunday | B11: AAPL – Apple Inc. | C11: MSFT – Microsoft Corp. | D11: ERIC – Ericsson AB | E11: ADS – Adidas AG | F11: SAP – SAP SE
A12: ='Sum and Cleaner'!$A$155 -> 2025-10-27 - Monday | B12: AAPL – Apple Inc. | C12: MSFT – Microsoft Corp. | D12: TELIA – Telia Company AB | E12: NVIDIA – NVIDIA Corp. | F12: EXXON – Exxon Mobil Corp.
A13: ='Sum and Cleaner'!$A$171 -> 2025-10-28 - Tuesday | B13: AAPL – Apple Inc. | C13: MSFT – Microsoft Corp. | D13: GOOGL – Alphabet Inc. | E13: TSLA – Tesla Inc. | F13: TELIA – Telia Company AB
A14: ='Sum and Cleaner'!$A$181 -> 2025-11-11 - Tuesday | B14: AZN – AstraZeneca plc | C14: EQTAB.ST – EQT AB | D14: HEXA‑B.ST – Hexagon AB | E14: SAABb.ST – Saab AB B | F14: BOL.ST – Boliden AB
A15: ='Sum and Cleaner'!$A$197 -> 2025-11-12 - Wednesday | B15: AZN – AstraZeneca plc | C15: EQT.ST – EQT AB | D15: HEXA‑B.ST – Hexagon AB | E15: SAABb.ST – Saab AB B | F15: BOL.ST – Boliden AB
A16: ='Sum and Cleaner'!$A$213 -> 2025-11-13 - Thursday | B16: MSFT – Microsoft Corporation | C16: NVDA – NVIDIA Corporation | D16: SAAB B – Saab AB B | E16: BOL – Boliden AB | F16: SKF – SKF AB
A17: ='Sum and Cleaner'!$A$229 -> 2025-11-14 - Friday | B17: ERIC – Telefonaktiebolaget LM Ericsson | C17: MSFT – Microsoft Corporation | D17: NVDA – NVIDIA Corporation | E17: VOLV‑B.ST – AB Volvo B | F17: BOL.ST – Boliden AB
A18: ='Sum and Cleaner'!$A$245 -> 2025-11-15 - Saturday | B18: MSFT – Microsoft Corporation | C18: NVDA – NVIDIA Corporation | D18: APM – APM Terminals | E18: LACX – LACX Mining Corp | F18: KBH – KB Home
A19: ='Sum and Cleaner'!$A$261 -> 2025-11-16 - Sunday | B19: STOR B.ST – Storskogen Group AB Simply Wall St | C19: BOL.ST – Boliden AB Investing.com+1 | D19: MSFT – Microsoft Corporation | E19: NVDA – NVIDIA Corporation | F19: SSAB B.ST – SSAB AB Wikipedia
A20: ='Sum and Cleaner'!$A$277 -> 2025-11-17 - Monday | B20: AAPL – Apple Inc. | C20: CSCO – Cisco Systems Inc. | D20: CAT – Caterpillar Inc. | E20: BHP – BHP Group Ltd. | F20: SKLGF – SKF Group (Class B, Sweden)
A21: ='Sum and Cleaner'!$A$293 -> 2025-11-18 - Tuesday | B21: AAPL – Apple Inc. | C21: CSCO – Cisco Systems Inc. | D21: CAT – Caterpillar Inc.
A22: ='Sum and Cleaner'!$A$298 -> 2025-10-14 - Tuesday | B22: ERIC – Telefonaktiebolaget LM Ericsson | C22: SAAB-B.ST – Saab AB | D22: AZN.ST – AstraZeneca PLC | E22: AMD – Advanced Micro Devices, Inc. | F22: MP – MP Materials Corp.
A23: ='Sum and Cleaner'!$A$313 -> 2025-10-16 - Thursday | B23: VOLV-B.ST – Volvo | C23: NIBE-B.ST – Nibe Industrier | D23: SPOT – Spotify Technology | E23: TSLA – Tesla | F23: SHEL – Shell
A24: ='Sum and Cleaner'!$A$328 -> 2025-10-18 - Saturday | B24: ERIC – Ericsson | C24: SAND.ST – Sandvik | D24: AAPL – Apple | E24: RIO – Rio Tinto | F24: ORCL – Oracle
A25: ='Sum and Cleaner'!$A$343 -> 2025-10-19 - Sunday | B25: SKF-B.ST – SKF | C25: EVO.ST – Evolution AB | D25: MSFT – Microsoft | E25: NVO – Novo Nordisk | F25: BP – BP Plc
A26: ='Sum and Cleaner'!$A$358 -> 2025-10-21 - Tuesday | B26: AAPL – Apple | C26: TSLA – Tesla | D26: SHEL – Shell | E26: RIO – Rio Tinto | F26: ERIC – Ericsson
A27: ='Sum and Cleaner'!$A$373 -> 2025-10-22 - Wednesday | B27: SHB A – Handelsbanken | C27: SAABB – Saab AB | D27: SSAB A – SSAB AB | E27: AAPL – Apple Inc | F27: SHEL – Shell plc
A28: ='Sum and Cleaner'!$A$394 -> 2025‑10‑29 - Wednesday | B28: AAPL – Apple Inc. | C28: MSFT – Microsoft Corp. | D28: ASML – ASML Holding NV | E28: VOLV B – Volvo AB B‑share | F28: BABA – Alibaba Group Holding Ltd
A29: ='Sum and Cleaner'!$A$410 -> 2025-10-30 - Thursday | B29: TER – Teradyne Inc. | C29: CAT – Caterpillar Inc. | D29: W – Wayfair Inc. | E29: AVGO – Broadcom Inc. | F29: AMD – Advanced Micro Devices Inc.
A30: ='Sum and Cleaner'!$A$426 -> 2025-10-31 - Friday | B30: MSFT – Microsoft Corp. | C30: GOOGL – Alphabet Inc. | D30: VOLV B – Volvo AB Class B | E30: ASML – ASML Holding NV | F30: BA – Boeing Co.
A31: ='Sum and Cleaner'!$A$442 -> 2025-11-01 - Saturday | B31: AMZN – Amazon.com Inc | C31: AAPL – Apple Inc | D31: EQTAB.ST – EQT AB Class B | E31: CAT – Caterpillar Inc | F31: GOOGL – Alphabet Inc
A32: ='Sum and Cleaner'!$A$458 -> 2025-11-02 - Sunday | B32: EQTAB.ST – EQT AB Class B (Sweden) | C32: MSFT – Microsoft Corporation | D32: NVDA – NVIDIA Corporation | E32: JNJ – Johnson & Johnson | F32: XOM – Exxon Mobil Corporation
A33: ='Sum and Cleaner'!$A$474 -> 2025-11-03 - Monday | B33: SAAB B.ST – Saab AB | C33: SAVE.ST – Nordnet AB | D33: EQTAB.ST – EQT AB Class B | E33: ERIC B.ST – Ericsson AB | F33: AAPL – Apple Inc
A34: ='Sum and Cleaner'!$A$490 -> 2025-11-04 - Tuesday | B34: EQTAB.ST – EQT AB Class B | C34: NVDA – NVIDIA Corporation | D34: VRTX – Vertex Pharmaceuticals | E34: DELL – Dell Technologies Inc. | F34: TELIA.ST – Telia Company
A35: ='Sum and Cleaner'!$A$516 -> 2025-11-19 - Wednesday | B35: CSCO – Cisco Systems Inc. | C35: AAPL – Apple Inc. | D35: CAT – Caterpillar Inc. | E35: BHP – BHP Group Ltd. | F35: SKFB.ST – SKF AB (Sweden)
A36: ='Sum and Cleaner'!$A$531 -> 2025-11-19 - Wednesday | B36: NVDA – NVIDIA Corp | C36: ERIC – Telefonaktiebolaget LM Ericsson | D36: VOLV-B.ST – AB Volvo (publ) B | E36: AZN.ST – AstraZeneca PLC | F36: VOLCAR-B.ST – Volvo Car AB (publ.)
A37: ='Sum and Cleaner'!$A$547 -> 2025-11-20 - Thursday | B37: NVDA – NVIDIA Corp | C37: AMD – Advanced Micro Devices Inc. | D37: WMT – Walmart Inc. | E37: SYNSAM.ST – Synsam AB (publ) | F37: HUFV-A.ST – Hufvudstaden AB (publ)
A38: ='Sum and Cleaner'!$A$563 -> 2025-11-21 - Friday | B38: NVDA – NVIDIA Corporation | C38: ERIC – Telefonaktiebolaget LM Ericsson | D38: WMT – Walmart Inc. | E38: TEL – Telia Company AB | F38: TAK – Takkt AG
A39: ='Sum and Cleaner'!$A$579 -> 2025-11-22 - Saturday | B39: AAPL – Apple Inc. | C39: SAP – SAP SE | D39: SAND.ST – Sandvik AB | E39: ORSTED.CO – Ørsted A/S | F39: TSLA – Tesla Inc.
A40: ='Sum and Cleaner'!$A$595 -> 2025-11-23 - Sunday | B40: SAAB B – Saab AB | C40: WBD – Warner Bros. Discovery, Inc. | D40: COST – Costco Wholesale Corporation | E40: LRCX – Lam Research Corporation | F40: ASML – ASML Holding N.V.
...

Sheet List to fetch
A1: Rec 1 | B1: Ticker
A2: NVDA – NVIDIA Corporation | B2: =LEFT(A2,6) -> NVDA –
A3: SECU-B.ST – Securitas AB | B3: =LEFT(A3,6) -> SECU-B
A4: TELIA.ST – Telia Company | B4: =LEFT(A4,6) -> TELIA.
A5: SWEC-B.ST – Sweco AB | B5: =LEFT(A5,6) -> SWEC-B
A6: SWEC-B.ST – Sweco AB | B6: =LEFT(A6,6) -> SWEC-B
A7: HEXA‑B.ST – Hexagon AB | B7: =LEFT(A7,6) -> HEXA‑B
A8: TSLA – Tesla Inc | B8: =LEFT(A8,6) -> TSLA –
A9: TELIA – Telia Company AB | B9: =LEFT(A9,6) -> TELIA
A10: AMD – Advanced Micro Devices Inc. | B10: =LEFT(A10,6) -> AMD –
A11: AAPL – Apple Inc. | B11: =LEFT(A11,6) -> AAPL –
A12: AAPL – Apple Inc. | B12: =LEFT(A12,6) -> AAPL –
A13: AAPL – Apple Inc. | B13: =LEFT(A13,6) -> AAPL –
... A230: CRH – CRH plc (S&P 500 inclusion announcement lifting name) Barron's | B230: =LEFT(A230,6) -> CRH –

Sheet changed on 161225
A1: For a short term trade, to be opened in the morning and closed at end of day, search for the latest major global news. Recommend EXACTLY 5 BUY tickers for short-term trade based on whatever you think is relevant. add very short reasoning after the recommendation.
A3: Start with one line containing the local date and day of week in Stockholm time formatted exactly as:
A4: YYYY-MM-DD / HH:MM - Monday
A6: Recs:
A7: TICKER – Company (short reasoning)
A8: TICKER – Company (short reasoning)
A9: TICKER – Company (short reasoning)
A10: TICKER – Company (short reasoning)
A11: TICKER – Company (short reasoning)
A14: Used to be: FRESH CATALYSTS AND MOMENTUM
