Workbook

Sheet llm reader copy paste from py
A1: folder_name | B1: ticker | C1: tendency | D1: confidence
A2: 45922 | B2: AAPL | C2: bearish | D2: 65
A3: 45922 | B3: AMZN | C3: neutral | D3: 70
A4: 45922 | B4: GOOGL | C4: neutral | D4: 65
A5: 45922 | B5: MSFT | C5: bearish | D5: 70
A6: 45922 | B6: NVDA | C6: bearish | D6: 70
A7: 45931 | B7: CRWD | C7: bullish | D7: 65
A8: 45931 | B8: IBM | C8: bearish | D8: 64
A9: 45931 | B9: MCD | C9: bearish | D9: 62
A10: 45931 | B10: MSFT | C10: bullish | D10: 63
A11: 45931 | B11: NVDA | C11: bearish | D11: 62
A12: 45932 | B12: INTC | C12: bearish | D12: 65
A13: 45932 | B13: MSFT | C13: neutral | D13: 62
... A63: 45957 | B63: TSLA | C63: bearish | D63: 62
A64: 45958 | B64: AAPL | C64: bearish | D64: 58 | E64: =_xlfn.CONCAT(A64,B64) -> 45958AAPL | F64: =C64 -> bearish | G64: =D64 -> 58
A65: 45958 | B65: AMD | C65: bearish | D65: 55 | E65: =_xlfn.CONCAT(A65,B65) -> 45958AMD | F65: =C65 -> bearish
A66: 45958 | B66: DYNE | C66: bullish | D66: 58 | E66: =_xlfn.CONCAT(A66,B66) -> 45958DYNE | F66: =C66 -> bullish
A67: 45958 | B67: LULU | C67: bullish | D67: 56 | E67: =_xlfn.CONCAT(A67,B67) -> 45958LULU | F67: =C67 -> bullish
A68: 45958 | B68: NVDA | C68: bullish | D68: 62 | E68: =_xlfn.CONCAT(A68,B68) -> 45958NVDA | F68: =C68 -> bullish
A69: 45959 | B69: AMZN | C69: bullish | D69: 56 | E69: =_xlfn.CONCAT(A69,B69) -> 45959AMZN | F69: =C69 -> bullish
A70: 45959 | B70: MSFT | C70: bullish | D70: 65 | E70: =_xlfn.CONCAT(A70,B70) -> 45959MSFT | F70: =C70 -> bullish
A71: 45959 | B71: NVDA | C71: bullish | D71: 58 | E71: =_xlfn.CONCAT(A71,B71) -> 45959NVDA | F71: =C71 -> bullish
A72: 45959 | B72: PYPL | C72: bearish | D72: 58 | E72: =_xlfn.CONCAT(A72,B72) -> 45959PYPL | F72: =C72 -> bearish
A73: 45959 | B73: UAL | C73: bullish | D73: 58 | E73: =_xlfn.CONCAT(A73,B73) -> 45959UAL | F73: =C73 -> bullish
A74: 45960 | B74: CAT | C74: bullish | D74: 57 | E74: =_xlfn.CONCAT(A74,B74) -> 45960CAT | F74: =C74 -> bullish
A75: 45960 | B75: CVNA | C75: bearish | D75: 62 | E75: =_xlfn.CONCAT(A75,B75) -> 45960CVNA | F75: =C75 -> bearish
A76: 45960 | B76: MSFT | C76: bullish | D76: 60 | E76: =_xlfn.CONCAT(A76,B76) -> 45960MSFT | F76: =C76 -> bullish
... A195: 45988 | B195: NVDA | C195: bullish | D195: 65 | E195: =_xlfn.CONCAT(A195,B195) -> 45988NVDA | F195: =C195 -> bullish

Sheet new
A1: Date | B1: Date | C1: Ticker | D1: id | E1: order | F1: order_amount | G1: Open | H1: High | I1: Low | J1: Close | K1: profit_made | L1: flow_name | M1: Daily_return_pct | N1: Intraday_Return
A2: 45953 | B2: 45953 | C2: MSFT | D2: 1 | E2: bullish | F2: 1 | G2: 521.48 | H2: 522.97 | I2: 517.64 | J2: 519.59 | K2: -1.89 | L2: trade_flow_v1 | M2: 0 | N2: -0.0036
A3: 45953 | B3: 45953 | C3: TSLA | D3: 2 | E3: bearish | F3: 1 | G3: 420 | H3: 449.4 | I3: 413.9 | J3: 448.98 | K3: 28.98 | L3: trade_flow_v1 | M3: 2.28 | N3: 0.069
A4: 45953 | B4: 45953 | C4: HON | D4: 3 | E4: bullish | F4: 1 | G4: 201.43 | H4: 208.44 | I4: 200.73 | J4: 206.74 | K4: 5.31 | L4: trade_flow_v1 | M4: 6.81 | N4: 0.0264
A5: 45953 | B5: 45953 | C5: AAL | D5: 4 | E5: bullish | F5: 1 | G5: 12.74 | H5: 13.04 | I5: 12.35 | J5: 12.77 | K5: 0.03 | L5: trade_flow_v1 | M5: 5.62 | N5: 0.0024
A6: 45954 | B6: 45954 | C6: AMD | D6: 8 | E6: bullish | F6: 1 | G6: 243.36 | H6: 253.39 | I6: 241.95 | J6: 252.92 | K6: 9.56 | L6: trade_flow_v1 | M6: 7.63 | N6: 0.0393
A7: 45954 | B7: 45954 | C7: MSFT | D7: 9 | E7: neutral | F7: 1 | G7: 521.81 | H7: 524.37 | I7: 519.74 | J7: 522.63 | K7: 0.82 | L7: trade_flow_v1 | M7: 0.59 | N7: 0.0016
A8: 45954 | B8: 45954 | C8: GM | D8: 10 | E8: bearish | F8: 1 | G8: 67.46 | H8: 69.7 | I8: 67.29 | J8: 69.66 | K8: 2.2 | L8: trade_flow_v1 | M8: 4.2 | N8: 0.0326
A9: 45954 | B9: 45954 | C9: TSLA | D9: 11 | E9: bullish | F9: 1 | G9: 446.83 | H9: 451.68 | I9: 430.17 | J9: 433.72 | K9: -13.11 | L9: trade_flow_v1 | M9: -3.4 | N9: -0.0293
A10: 45954 | B10: 45954 | C10: PG | D10: 12 | E10: bullish | F10: 1 | G10: 156.4 | H10: 157.4 | I10: 151.53 | J10: 152.49 | K10: -3.91 | L10: trade_flow_v1 | M10: 0.88 | N10: -0.025
A11: 45954 | B11: 45954 | C11: AMD | D11: 13 | G11: 243.36 | H11: 253.39 | I11: 241.95 | J11: 252.92 | K11: 9.56 | L11: trade_flow_v1 | M11: 7.63 | N11: 0.0393
A12: 45954 | B12: 45954 | C12: MSFT | D12: 14 | G12: 521.81 | H12: 524.37 | I12: 519.74 | J12: 522.63 | K12: 0.82 | L12: trade_flow_v1 | M12: 0.59 | N12: 0.0016
A13: 45954 | B13: 45954 | C13: GM | D13: 15 | G13: 67.46 | H13: 69.7 | I13: 67.29 | J13: 69.66 | K13: 2.2 | L13: trade_flow_v1 | M13: 4.2 | N13: 0.0326
A14: 45954 | B14: 45954 | C14: TSLA | D14: 16 | G14: 446.83 | H14: 451.68 | I14: 430.17 | J14: 433.72 | K14: -13.11 | L14: trade_flow_v1 | M14: -3.4 | N14: -0.0293
A15: 45954 | B15: 45954 | C15: PG | D15: 17 | G15: 156.4 | H15: 157.4 | I15: 151.53 | J15: 152.49 | K15: -3.91 | L15: trade_flow_v1 | M15: 0.88 | N15: -0.025
A16: 45954 | B16: 45954 | C16: AMD | D16: 18 | G16: 243.36 | H16: 253.39 | I16: 241.95 | J16: 252.92 | K16: 9.56 | L16: trade_flow_v1 | M16: 7.63 | N16: 0.0393
A17: 45954 | B17: 45954 | C17: MSFT | D17: 19 | G17: 521.81 | H17: 524.37 | I17: 519.74 | J17: 522.63 | K17: 0.82 | L17: trade_flow_v1 | M17: 0.59 | N17: 0.0016
A18: 45954 | B18: 45954 | C18: AAL | D18: 20 | E18: bullish | F18: 1 | G18: 13 | H18: 13.89 | I18: 12.9 | J18: 13.78 | K18: 0.78 | L18: trade_flow_v1 | M18: 7.91 | N18: 0.06
A19: 45954 | B19: 45954 | C19: HON | D19: 21 | E19: bullish | F19: 1 | G19: 206.99 | H19: 206.99 | I19: 201.2 | J19: 202.5 | K19: -4.49 | L19: trade_flow_v1 | M19: -2.05 | N19: -0.0217
A20: 45954 | B20: 45954 | C20: GM | D20: 22 | G20: 67.46 | H20: 69.7 | I20: 67.29 | J20: 69.66 | K20: 2.2 | L20: trade_flow_v1 | M20: 4.2 | N20: 0.0326
A21: 45955 | B21: 45955 | C21: AMD | D21: 23 | E21: bullish | F21: 1 | G21: 243.36 | H21: 253.39 | I21: 241.95 | J21: 252.92 | K21: 9.56 | L21: trade_flow_v1 | M21: 7.63 | N21: 0.0393
A22: 45955 | B22: 45955 | C22: MSFT | D22: 24 | E22: bullish | F22: 1 | G22: 521.81 | H22: 524.37 | I22: 519.74 | J22: 522.63 | K22: 0.82 | L22: trade_flow_v1 | M22: 0.59 | N22: 0.0016
A23: 45955 | B23: 45955 | C23: AAL | D23: 25 | E23: bullish | F23: 1 | G23: 13 | H23: 13.89 | I23: 12.9 | J23: 13.78 | K23: 0.78 | L23: trade_flow_v1 | M23: 7.91 | N23: 0.06
A24: 45955 | B24: 45955 | C24: HON | D24: 26 | E24: bullish | F24: 1 | G24: 206.99 | H24: 206.99 | I24: 201.2 | J24: 202.5 | K24: -4.49 | L24: trade_flow_v1 | M24: -2.05 | N24: -0.0217
A25: 45955 | B25: 45955 | C25: PFE | D25: 27 | E25: bearish | F25: 1 | G25: 24.27 | H25: 24.4 | I25: 24.25 | J25: 24.33 | K25: 0.06 | L25: trade_flow_v1 | M25: 0.36 | N25: 0.0025
A26: 45956 | B26: 45956 | C26: AMD | D26: 28 | E26: bullish | F26: 1 | G26: 243.36 | H26: 253.39 | I26: 241.95 | J26: 252.92 | K26: 9.56 | L26: trade_flow_v1 | M26: 7.63 | N26: 0.0393
A27: 45956 | B27: 45956 | C27: MSFT | D27: 29 | E27: bullish | F27: 1 | G27: 521.81 | H27: 524.37 | I27: 519.74 | J27: 522.63 | K27: 0.82 | L27: trade_flow_v1 | M27: 0.59 | N27: 0.0016
A28: 45956 | B28: 45956 | C28: AAL | D28: 30 | E28: bullish | F28: 1 | G28: 13 | H28: 13.89 | I28: 12.9 | J28: 13.78 | K28: 0.78 | L28: trade_flow_v1 | M28: 7.91 | N28: 0.06
A29: 45956 | B29: 45956 | C29: HON | D29: 31 | E29: bullish | F29: 1 | G29: 206.99 | H29: 206.99 | I29: 201.2 | J29: 202.5 | K29: -4.49 | L29: trade_flow_v1 | M29: -2.05 | N29: -0.0217
A30: 45956 | B30: 45956 | C30: PFE | D30: 32 | E30: bearish | F30: 1 | G30: 24.27 | H30: 24.4 | I30: 24.25 | J30: 24.33 | K30: 0.06 | L30: trade_flow_v1 | M30: 0.36 | N30: 0.0025
A31: 45956 | B31: 45956 | C31: AMD | D31: 33 | E31: bullish | F31: 1 | G31: 243.36 | H31: 253.39 | I31: 241.95 | J31: 252.92 | K31: 9.56 | L31: trade_flow_v1 | M31: 7.63 | N31: 0.0393
A32: 45956 | B32: 45956 | C32: MSFT | D32: 34 | E32: bullish | F32: 1 | G32: 521.81 | H32: 524.37 | I32: 519.74 | J32: 522.63 | K32: 0.82 | L32: trade_flow_v1 | M32: 0.59 | N32: 0.0016
... A110: 45957 | B110: 45957 | C110: PFE | D110: 112 | E110: bearish | F110: 1 | G110: 24.31 | H110: 24.37 | I110: 24.2 | J110: 24.34 | K110: 0.03 | L110: trade_flow_v1 | M110: 0.04 | N110: 0.0012
A111: 45957 | B111: 45957 | C111: AMD | D111: 113 | G111: 257.88 | H111: 260.42 | I111: 249.8 | J111: 259.67 | K111: 1.79 | L111: trade_flow_v1 | M111: 2.67 | N111: 0.0069
A112: 45957 | B112: 45957 | C112: MSFT | D112: 114 | G112: 530.79 | H112: 533.58 | I112: 528.02 | J112: 530.53 | K112: -0.26 | L112: trade_flow_v1 | M112: 1.51 | N112: -0.0005
A113: 45957 | B113: 45957 | C113: AAL | D113: 115 | G113: 13.78 | H113: 13.85 | I113: 13.34 | J113: 13.41 | K113: -0.37 | L113: trade_flow_v1 | M113: -2.69 | N113: -0.0269
A114: 45957 | B114: 45957 | C114: HON | D114: 116 | G114: 205.14 | H114: 205.38 | I114: 201.15 | J114: 201.5 | K114: -3.64 | L114: trade_flow_v1 | M114: -0.5 | N114: -0.0177
A115: 45957 | B115: 45957 | C115: PFE | D115: 117 | G115: 24.31 | H115: 24.37 | I115: 24.2 | J115: 24.34 | K115: 0.03 | L115: trade_flow_v1 | M115: 0.04 | N115: 0.0012
A116: 45957 | B116: 45957 | C116: DYN | D116: 118 | E116: bearish | F116: 1 | G116: 23.4 | H116: 24.95 | I116: 23 | J116: 24.17 | K116: 0.77 | L116: trade_flow_v1 | M116: 41.18 | N116: 0.0329
A117: 45957 | B117: 45957 | C117: LULU | D117: 119 | E117: bearish | F117: 1 | G117: 186.43 | H117: 186.91 | I117: 181.33 | J117: 181.39 | K117: -5.04 | L117: trade_flow_v1 | M117: 1.81 | N117: -0.027
...

Sheet edit
A1: Date | B1: Date | C1: NEW TICKET | D1: OLD TICKER | E1: id | F1: order | G1: order_amount | H1: Open | I1: High | J1: Low | K1: Close | L1: profit_made | M1: flow_name | N1: Daily_return_pct | O1: Intraday_Return
A2: 45953 | B2: 45953 | C2: MSFT | D2: MSFT | E2: 1 | F2: bullish | G2: 1 | H2: 521.48 | I2: 522.97 | J2: 517.64 | K2: 519.59 | L2: -1.89 | M2: trade_flow_v1 | N2: 0 | O2: -0.0036
A3: 45953 | B3: 45953 | C3: TSLA | D3: TSLA | E3: 2 | F3: bearish | G3: 1 | H3: 420 | I3: 449.4 | J3: 413.9 | K3: 448.98 | L3: 28.98 | M3: trade_flow_v1 | N3: 2.28 | O3: 0.069
A4: 45953 | B4: 45953 | C4: HON | D4: HON | E4: 3 | F4: bullish | G4: 1 | H4: 201.43 | I4: 208.44 | J4: 200.73 | K4: 206.74 | L4: 5.31 | M4: trade_flow_v1 | N4: 6.81 | O4: 0.0264
A5: 45953 | B5: 45953 | C5: AAL | D5: AAL | E5: 4 | F5: bullish | G5: 1 | H5: 12.74 | I5: 13.04 | J5: 12.35 | K5: 12.77 | L5: 0.03 | M5: trade_flow_v1 | N5: 5.62 | O5: 0.0024
A6: 45954 | B6: 45954 | C6: AMD | D6: AMD | E6: 8 | F6: bullish | G6: 1 | H6: 243.36 | I6: 253.39 | J6: 241.95 | K6: 252.92 | L6: 9.56 | M6: trade_flow_v1 | N6: 7.63 | O6: 0.0393
A7: 45954 | B7: 45954 | C7: MSFT | D7: MSFT | E7: 9 | F7: neutral | G7: 1 | H7: 521.81 | I7: 524.37 | J7: 519.74 | K7: 522.63 | L7: 0.82 | M7: trade_flow_v1 | N7: 0.59 | O7: 0.0016
A8: 45954 | B8: 45954 | C8: GM | D8: GM | E8: 10 | F8: bearish | G8: 1 | H8: 67.46 | I8: 69.7 | J8: 67.29 | K8: 69.66 | L8: 2.2 | M8: trade_flow_v1 | N8: 4.2 | O8: 0.0326
A9: 45954 | B9: 45954 | C9: TSLA | D9: TSLA | E9: 11 | F9: bullish | G9: 1 | H9: 446.83 | I9: 451.68 | J9: 430.17 | K9: 433.72 | L9: -13.11 | M9: trade_flow_v1 | N9: -3.4 | O9: -0.0293
A10: 45954 | B10: 45954 | C10: PG | D10: PG | E10: 12 | F10: bullish | G10: 1 | H10: 156.4 | I10: 157.4 | J10: 151.53 | K10: 152.49 | L10: -3.91 | M10: trade_flow_v1 | N10: 0.88 | O10: -0.025
A11: 45954 | B11: 45954 | C11: AMD | D11: AMD | E11: 13 | H11: 243.36 | I11: 253.39 | J11: 241.95 | K11: 252.92 | L11: 9.56 | M11: trade_flow_v1 | N11: 7.63 | O11: 0.0393
A12: 45954 | B12: 45954 | C12: MSFT | D12: MSFT | E12: 14 | H12: 521.81 | I12: 524.37 | J12: 519.74 | K12: 522.63 | L12: 0.82 | M12: trade_flow_v1 | N12: 0.59 | O12: 0.0016
A13: 45954 | B13: 45954 | C13: GM | D13: GM | E13: 15 | H13: 67.46 | I13: 69.7 | J13: 67.29 | K13: 69.66 | L13: 2.2 | M13: trade_flow_v1 | N13: 4.2 | O13: 0.0326
A14: 45954 | B14: 45954 | C14: TSLA | D14: TSLA | E14: 16 | H14: 446.83 | I14: 451.68 | J14: 430.17 | K14: 433.72 | L14: -13.11 | M14: trade_flow_v1 | N14: -3.4 | O14: -0.0293
A15: 45954 | B15: 45954 | C15: PG | D15: PG | E15: 17 | H15: 156.4 | I15: 157.4 | J15: 151.53 | K15: 152.49 | L15: -3.91 | M15: trade_flow_v1 | N15: 0.88 | O15: -0.025
A16: 45954 | B16: 45954 | C16: AMD | D16: AMD | E16: 18 | H16: 243.36 | I16: 253.39 | J16: 241.95 | K16: 252.92 | L16: 9.56 | M16: trade_flow_v1 | N16: 7.63 | O16: 0.0393
A17: 45954 | B17: 45954 | C17: MSFT | D17: MSFT | E17: 19 | H17: 521.81 | I17: 524.37 | J17: 519.74 | K17: 522.63 | L17: 0.82 | M17: trade_flow_v1 | N17: 0.59 | O17: 0.0016
A18: 45954 | B18: 45954 | C18: AAL | D18: AAL | E18: 20 | F18: bullish | G18: 1 | H18: 13 | I18: 13.89 | J18: 12.9 | K18: 13.78 | L18: 0.78 | M18: trade_flow_v1 | N18: 7.91 | O18: 0.06
A19: 45954 | B19: 45954 | C19: HON | D19: HON | E19: 21 | F19: bullish | G19: 1 | H19: 206.99 | I19: 206.99 | J19: 201.2 | K19: 202.5 | L19: -4.49 | M19: trade_flow_v1 | N19: -2.05 | O19: -0.0217
A20: 45954 | B20: 45954 | C20: GM | D20: GM | E20: 22 | H20: 67.46 | I20: 69.7 | J20: 67.29 | K20: 69.66 | L20: 2.2 | M20: trade_flow_v1 | N20: 4.2 | O20: 0.0326
A21: 45955 | B21: 45955 | C21: AMD | D21: AMD | E21: 23 | F21: bullish | G21: 1 | H21: 243.36 | I21: 253.39 | J21: 241.95 | K21: 252.92 | L21: 9.56 | M21: trade_flow_v1 | N21: 7.63 | O21: 0.0393
A22: 45955 | B22: 45955 | C22: MSFT | D22: MSFT | E22: 24 | F22: bullish | G22: 1 | H22: 521.81 | I22: 524.37 | J22: 519.74 | K22: 522.63 | L22: 0.82 | M22: trade_flow_v1 | N22: 0.59 | O22: 0.0016
A23: 45955 | B23: 45955 | C23: AAL | D23: AAL | E23: 25 | F23: bullish | G23: 1 | H23: 13 | I23: 13.89 | J23: 12.9 | K23: 13.78 | L23: 0.78 | M23: trade_flow_v1 | N23: 7.91 | O23: 0.06
A24: 45955 | B24: 45955 | C24: HON | D24: HON | E24: 26 | F24: bullish | G24: 1 | H24: 206.99 | I24: 206.99 | J24: 201.2 | K24: 202.5 | L24: -4.49 | M24: trade_flow_v1 | N24: -2.05 | O24: -0.0217
A25: 45955 | B25: 45955 | C25: PFE | D25: PFE | E25: 27 | F25: bearish | G25: 1 | H25: 24.27 | I25: 24.4 | J25: 24.25 | K25: 24.33 | L25: 0.06 | M25: trade_flow_v1 | N25: 0.36 | O25: 0.0025
A26: 45956 | B26: 45956 | C26: AMD | D26: AMD | E26: 28 | F26: bullish | G26: 1 | H26: 243.36 | I26: 253.39 | J26: 241.95 | K26: 252.92 | L26: 9.56 | M26: trade_flow_v1 | N26: 7.63 | O26: 0.0393
A27: 45956 | B27: 45956 | C27: MSFT | D27: MSFT | E27: 29 | F27: bullish | G27: 1 | H27: 521.81 | I27: 524.37 | J27: 519.74 | K27: 522.63 | L27: 0.82 | M27: trade_flow_v1 | N27: 0.59 | O27: 0.0016
A28: 45956 | B28: 45956 | C28: AAL | D28: AAL | E28: 30 | F28: bullish | G28: 1 | H28: 13 | I28: 13.89 | J28: 12.9 | K28: 13.78 | L28: 0.78 | M28: trade_flow_v1 | N28: 7.91 | O28: 0.06
A29: 45956 | B29: 45956 | C29: HON | D29: HON | E29: 31 | F29: bullish | G29: 1 | H29: 206.99 | I29: 206.99 | J29: 201.2 | K29: 202.5 | L29: -4.49 | M29: trade_flow_v1 | N29: -2.05 | O29: -0.0217
A30: 45956 | B30: 45956 | C30: PFE | D30: PFE | E30: 32 | F30: bearish | G30: 1 | H30: 24.27 | I30: 24.4 | J30: 24.25 | K30: 24.33 | L30: 0.06 | M30: trade_flow_v1 | N30: 0.36 | O30: 0.0025
A31: 45956 | B31: 45956 | C31: AMD | D31: AMD | E31: 33 | F31: bullish | G31: 1 | H31: 243.36 | I31: 253.39 | J31: 241.95 | K31: 252.92 | L31: 9.56 | M31: trade_flow_v1 | N31: 7.63 | O31: 0.0393
A32: 45956 | B32: 45956 | C32: MSFT | D32: MSFT | E32: 34 | F32: bullish | G32: 1 | H32: 521.81 | I32: 524.37 | J32: 519.74 | K32: 522.63 | L32: 0.82 | M32: trade_flow_v1 | N32: 0.59 | O32: 0.0016
... A110: 45957 | B110: 45957 | C110: PFE | D110: PFE | E110: 112 | F110: bearish | G110: 1 | H110: 24.31 | I110: 24.37 | J110: 24.2 | K110: 24.34 | L110: 0.03 | M110: trade_flow_v1 | N110: 0.04 | O110: 0.0012
A111: 45957 | B111: 45957 | C111: AMD | D111: AMD | E111: 113 | H111: 257.88 | I111: 260.42 | J111: 249.8 | K111: 259.67 | L111: 1.79 | M111: trade_flow_v1 | N111: 2.67 | O111: 0.0069
A112: 45957 | B112: 45957 | C112: MSFT | D112: MSFT | E112: 114 | H112: 530.79 | I112: 533.58 | J112: 528.02 | K112: 530.53 | L112: -0.26 | M112: trade_flow_v1 | N112: 1.51 | O112: -0.0005
A113: 45957 | B113: 45957 | C113: AAL | D113: AAL | E113: 115 | H113: 13.78 | I113: 13.85 | J113: 13.34 | K113: 13.41 | L113: -0.37 | M113: trade_flow_v1 | N113: -2.69 | O113: -0.0269
A114: 45957 | B114: 45957 | C114: HON | D114: HON | E114: 116 | H114: 205.14 | I114: 205.38 | J114: 201.15 | K114: 201.5 | L114: -3.64 | M114: trade_flow_v1 | N114: -0.5 | O114: -0.0177
A115: 45957 | B115: 45957 | C115: PFE | D115: PFE | E115: 117 | H115: 24.31 | I115: 24.37 | J115: 24.2 | K115: 24.34 | L115: 0.03 | M115: trade_flow_v1 | N115: 0.04 | O115: 0.0012
A116: 45957 | B116: 45957 | C116: DYN | D116: DYN | E116: 118 | F116: bearish | G116: 1 | H116: 23.4 | I116: 24.95 | J116: 23 | K116: 24.17 | L116: 0.77 | M116: trade_flow_v1 | N116: 41.18 | O116: 0.0329
A117: 45957 | B117: 45957 | C117: LULU | D117: LULU | E117: 119 | F117: bearish | G117: 1 | H117: 186.43 | I117: 186.91 | J117: 181.33 | K117: 181.39 | L117: -5.04 | M117: trade_flow_v1 | N117: 1.81 | O117: -0.027
...
