Workbook

Sheet 2025-11-19 to 11-25
A1: 2025-11-05 - Wednesday
A2: Recs:
A3: NVDA – NVIDIA Corporation
A4: AAPL – Apple Inc.
A5: MSFT – Microsoft Corporation
A6: ERICb.ST – Telefonaktiebolaget LM Ericsson B
A7: BOL – The Boliden Company
A8: Perf (prev recs):
A9: N/A
A10: N/A
A11: N/A
A12: N/A
... A529: S&P500 N/A

Sheet 2
A1: 2025-11-19 - Wednesday
A2: Recs:
A3: NVDA – NVIDIA Corp
A4: ERIC – Telefonaktiebolaget LM Ericsson
A5: VOLV-B.ST – AB Volvo (publ) B
A6: AZN.ST – AstraZeneca PLC
A7: VOLCAR-B.ST – Volvo Car AB (publ.)
A8: Perf (prev recs):
A9: N/A
A10: N/A
A11: N/A
A12: N/A
... A113: This automation has been paused due to too many unread executions. You can resume it in automations settings or by asking ChatGPT.

Sheet 3
A1: Recs:
A2: GEV - GE Vernova Inc (breakout after strong catalyst and technical momentum)Investors+1
A3: PLTR - Palantir Technologies (recent contract win and positive flow)Barron's
A4: SATS - EchoStar Corp (premarket strength and sector interest)Barron's
A5: AVTR - Avantor Inc (premarket gains signaling momentum)Barron's
A6: FSLR - First Solar (sector news on project supply momentum)Simply Wall St
A8: Prev days return S&P500 +0.67%investing.com
A10: 2025‑12‑12 / 08:15 - Friday
A12: Recs:
A13: NVDA - Nvidia (momentum from AI demand and trading strength)
A14: MSFT - Microsoft (strong cloud earnings sentiment driving flow)
A15: TSLA - Tesla (price breakout and volume spike)
... A52: Prev days return S&P500 -1.07

Sheet Sum and Cleaner
A1: String | B1: Is date? | C1: Date | D1: Rec 1 | E1: Rec 2 | F1: Rec 3 | G1: Rec 4 | H1: Rec 5
A2: 2025-11-05 - Wednesday | B2: =ISNUMBER(LEFT(A2,4)+1-1) -> TRUE | C2: =IF(B2,LEFT(A2,10),C1) -> 2025-11-05 | D2: =A4 -> NVDA – NVIDIA Corporation | E2: =A5 -> AAPL – Apple Inc. | F2: =A6 -> MSFT – Microsoft Corporation | G2: =A7 -> ERICb.ST – Telefonaktiebolaget LM Ericsson B | H2: =A8 -> BOL – The Boliden Company
A3: Recs: | B3: =ISNUMBER(LEFT(A3,4)+1-1) -> FALSE | C3: =IF(B3,LEFT(A3,10),C2) -> 2025-11-05 | D3: =A5 -> AAPL – Apple Inc. | E3: =A6 -> MSFT – Microsoft Corporation | F3: =A7 -> ERICb.ST – Telefonaktiebolaget LM Ericsson B | G3: =A8 -> BOL – The Boliden Company | H3: =A9 -> Perf (prev recs):
A4: NVDA – NVIDIA Corporation | B4: =ISNUMBER(LEFT(A4,4)+1-1) -> FALSE | C4: =IF(B4,LEFT(A4,10),C3) -> 2025-11-05 | D4: =A6 -> MSFT – Microsoft Corporation | E4: =A7 -> ERICb.ST – Telefonaktiebolaget LM Ericsson B | F4: =A8 -> BOL – The Boliden Company | G4: =A9 -> Perf (prev recs): | H4: =A10 -> N/A
A5: AAPL – Apple Inc. | B5: =ISNUMBER(LEFT(A5,4)+1-1) -> FALSE | C5: =IF(B5,LEFT(A5,10),C4) -> 2025-11-05 | D5: =A7 -> ERICb.ST – Telefonaktiebolaget LM Ericsson B | E5: =A8 -> BOL – The Boliden Company | F5: =A9 -> Perf (prev recs): | G5: =A10 -> N/A | H5: =A11 -> N/A
A6: MSFT – Microsoft Corporation | B6: =ISNUMBER(LEFT(A6,4)+1-1) -> FALSE | C6: =IF(B6,LEFT(A6,10),C5) -> 2025-11-05 | D6: =A8 -> BOL – The Boliden Company | E6: =A9 -> Perf (prev recs): | F6: =A10 -> N/A | G6: =A11 -> N/A | H6: =A12 -> N/A
A7: ERICb.ST – Telefonaktiebolaget LM Ericsson B | B7: =ISNUMBER(LEFT(A7,4)+1-1) -> FALSE | C7: =IF(B7,LEFT(A7,10),C6) -> 2025-11-05 | D7: =A9 -> Perf (prev recs): | E7: =A10 -> N/A | F7: =A11 -> N/A | G7: =A12 -> N/A | H7: =A13 -> N/A
A8: BOL – The Boliden Company | B8: =ISNUMBER(LEFT(A8,4)+1-1) -> FALSE | C8: =IF(B8,LEFT(A8,10),C7) -> 2025-11-05 | D8: =A10 -> N/A | E8: =A11 -> N/A | F8: =A12 -> N/A | G8: =A13 -> N/A | H8: =A14 -> N/A
A9: Perf (prev recs): | B9: =ISNUMBER(LEFT(A9,4)+1-1) -> FALSE | C9: =IF(B9,LEFT(A9,10),C8) -> 2025-11-05 | D9: =A11 -> N/A | E9: =A12 -> N/A | F9: =A13 -> N/A | G9: =A14 -> N/A | H9: =A15 -> Avg N/A
A10: N/A | B10: =ISNUMBER(LEFT(A10,4)+1-1) -> FALSE | C10: =IF(B10,LEFT(A10,10),C9) -> 2025-11-05 | D10: =A12 -> N/A | E10: =A13 -> N/A | F10: =A14 -> N/A | G10: =A15 -> Avg N/A | H10: =A16 -> S&P500 +X.XX%
A11: N/A | B11: =ISNUMBER(LEFT(A11,4)+1-1) -> FALSE | C11: =IF(B11,LEFT(A11,10),C10) -> 2025-11-05 | D11: =A13 -> N/A | E11: =A14 -> N/A | F11: =A15 -> Avg N/A | G11: =A16 -> S&P500 +X.XX% | H11: =A17 -> 0
A12: N/A | B12: =ISNUMBER(LEFT(A12,4)+1-1) -> FALSE | C12: =IF(B12,LEFT(A12,10),C11) -> 2025-11-05 | D12: =A14 -> N/A | E12: =A15 -> Avg N/A | F12: =A16 -> S&P500 +X.XX% | G12: =A17 -> 0 | H12: =A18 -> 2025-11-06 - Thursday
A13: N/A | B13: =ISNUMBER(LEFT(A13,4)+1-1) -> FALSE | C13: =IF(B13,LEFT(A13,10),C12) -> 2025-11-05 | D13: =A15 -> Avg N/A | E13: =A16 -> S&P500 +X.XX% | F13: =A17 -> 0 | G13: =A18 -> 2025-11-06 - Thursday | H13: =A19 -> Recs:
... A16: S&P500 +X.XX% | B16: =ISNUMBER(LEFT(A16,4)+1-1) -> FALSE | C16: =IF(B16,LEFT(A16,10),C15) -> 2025-11-05 | D16: =A18 -> 2025-11-06 - Thursday | E16: =A19 -> Recs: | F16: =A20 -> SECU-B.ST – Securitas AB | G16: =A21 -> ERIC-B.ST – Ericsson B | H16: =A22 -> TELIA.ST – Telia Company
B17: =ISNUMBER(LEFT(A17,4)+1-1) -> FALSE | C17: =IF(B17,LEFT(A17,10),C16) -> 2025-11-05 | D17: =A19 -> Recs: | E17: =A20 -> SECU-B.ST – Securitas AB | F17: =A21 -> ERIC-B.ST – Ericsson B | G17: =A22 -> TELIA.ST – Telia Company | H17: =A23 -> SAAB-B.ST – Saab AB
A18: 2025-11-06 - Thursday | B18: =ISNUMBER(LEFT(A18,4)+1-1) -> TRUE | C18: =IF(B18,LEFT(A18,10),C17) -> 2025-11-06 | D18: =A20 -> SECU-B.ST – Securitas AB | E18: =A21 -> ERIC-B.ST – Ericsson B | F18: =A22 -> TELIA.ST – Telia Company | G18: =A23 -> SAAB-B.ST – Saab AB | H18: =A24 -> VOLV-B.ST – AB Volvo B
A19: Recs: | B19: =ISNUMBER(LEFT(A19,4)+1-1) -> FALSE | C19: =IF(B19,LEFT(A19,10),C18) -> 2025-11-06 | D19: =A21 -> ERIC-B.ST – Ericsson B | E19: =A22 -> TELIA.ST – Telia Company | F19: =A23 -> SAAB-B.ST – Saab AB | G19: =A24 -> VOLV-B.ST – AB Volvo B | H19: =A25 -> Perf (prev recs):
A20: SECU-B.ST – Securitas AB | B20: =ISNUMBER(LEFT(A20,4)+1-1) -> FALSE | C20: =IF(B20,LEFT(A20,10),C19) -> 2025-11-06 | D20: =A22 -> TELIA.ST – Telia Company | E20: =A23 -> SAAB-B.ST – Saab AB | F20: =A24 -> VOLV-B.ST – AB Volvo B | G20: =A25 -> Perf (prev recs): | H20: =A26 -> N/A
A21: ERIC-B.ST – Ericsson B | B21: =ISNUMBER(LEFT(A21,4)+1-1) -> FALSE | C21: =IF(B21,LEFT(A21,10),C20) -> 2025-11-06 | D21: =A23 -> SAAB-B.ST – Saab AB | E21: =A24 -> VOLV-B.ST – AB Volvo B | F21: =A25 -> Perf (prev recs): | G21: =A26 -> N/A | H21: =A27 -> 0
A22: TELIA.ST – Telia Company | B22: =ISNUMBER(LEFT(A22,4)+1-1) -> FALSE | C22: =IF(B22,LEFT(A22,10),C21) -> 2025-11-06 | D22: =A24 -> VOLV-B.ST – AB Volvo B | E22: =A25 -> Perf (prev recs): | F22: =A26 -> N/A | G22: =A27 -> 0 | H22: =A28 -> 2025-11-07 - Friday
A23: SAAB-B.ST – Saab AB | B23: =ISNUMBER(LEFT(A23,4)+1-1) -> FALSE | C23: =IF(B23,LEFT(A23,10),C22) -> 2025-11-06 | D23: =A25 -> Perf (prev recs): | E23: =A26 -> N/A | F23: =A27 -> 0 | G23: =A28 -> 2025-11-07 - Friday | H23: =A29 -> Recs:
A24: VOLV-B.ST – AB Volvo B | B24: =ISNUMBER(LEFT(A24,4)+1-1) -> FALSE | C24: =IF(B24,LEFT(A24,10),C23) -> 2025-11-06 | D24: =A26 -> N/A | E24: =A27 -> 0 | F24: =A28 -> 2025-11-07 - Friday | G24: =A29 -> Recs: | H24: =A30 -> TELIA.ST – Telia Company
A25: Perf (prev recs): | B25: =ISNUMBER(LEFT(A25,4)+1-1) -> FALSE | C25: =IF(B25,LEFT(A25,10),C24) -> 2025-11-06 | D25: =A27 -> 0 | E25: =A28 -> 2025-11-07 - Friday | F25: =A29 -> Recs: | G25: =A30 -> TELIA.ST – Telia Company | H25: =A31 -> ERIC-B.ST – Ericsson B
A26: N/A | B26: =ISNUMBER(LEFT(A26,4)+1-1) -> FALSE | C26: =IF(B26,LEFT(A26,10),C25) -> 2025-11-06 | D26: =A28 -> 2025-11-07 - Friday | E26: =A29 -> Recs: | F26: =A30 -> TELIA.ST – Telia Company | G26: =A31 -> ERIC-B.ST – Ericsson B | H26: =A32 -> SAAB-B.ST – Saab AB
B27: =ISNUMBER(LEFT(A27,4)+1-1) -> FALSE | C27: =IF(B27,LEFT(A27,10),C26) -> 2025-11-06 | D27: =A29 -> Recs: | E27: =A30 -> TELIA.ST – Telia Company | F27: =A31 -> ERIC-B.ST – Ericsson B | G27: =A32 -> SAAB-B.ST – Saab AB | H27: =A33 -> VOLV-B.ST – AB Volvo B
A28: 2025-11-07 - Friday | B28: =ISNUMBER(LEFT(A28,4)+1-1) -> TRUE | C28: =IF(B28,LEFT(A28,10),C27) -> 2025-11-07 | D28: =A30 -> TELIA.ST – Telia Company | E28: =A31 -> ERIC-B.ST – Ericsson B | F28: =A32 -> SAAB-B.ST – Saab AB | G28: =A33 -> VOLV-B.ST – AB Volvo B | H28: =A34 -> NOK – Nokia Corporation
A29: Recs: | B29: =ISNUMBER(LEFT(A29,4)+1-1) -> FALSE | C29: =IF(B29,LEFT(A29,10),C28) -> 2025-11-07 | D29: =A31 -> ERIC-B.ST – Ericsson B | E29: =A32 -> SAAB-B.ST – Saab AB | F29: =A33 -> VOLV-B.ST – AB Volvo B | G29: =A34 -> NOK – Nokia Corporation | H29: =A35 -> Perf (prev recs):
A30: TELIA.ST – Telia Company | B30: =ISNUMBER(LEFT(A30,4)+1-1) -> FALSE | C30: =IF(B30,LEFT(A30,10),C29) -> 2025-11-07 | D30: =A32 -> SAAB-B.ST – Saab AB | E30: =A33 -> VOLV-B.ST – AB Volvo B | F30: =A34 -> NOK – Nokia Corporation | G30: =A35 -> Perf (prev recs): | H30: =A36 -> SECU-B.ST N/A
A31: ERIC-B.ST – Ericsson B | B31: =ISNUMBER(LEFT(A31,4)+1-1) -> FALSE | C31: =IF(B31,LEFT(A31,10),C30) -> 2025-11-07 | D31: =A33 -> VOLV-B.ST – AB Volvo B | E31: =A34 -> NOK – Nokia Corporation | F31: =A35 -> Perf (prev recs): | G31: =A36 -> SECU-B.ST N/A | H31: =A37 -> TELIA.ST N/A
A32: SAAB-B.ST – Saab AB | B32: =ISNUMBER(LEFT(A32,4)+1-1) -> FALSE | C32: =IF(B32,LEFT(A32,10),C31) -> 2025-11-07 | D32: =A34 -> NOK – Nokia Corporation | E32: =A35 -> Perf (prev recs): | F32: =A36 -> SECU-B.ST N/A | G32: =A37 -> TELIA.ST N/A | H32: =A38 -> SAAB-B.ST N/A
A33: VOLV-B.ST – AB Volvo B | B33: =ISNUMBER(LEFT(A33,4)+1-1) -> FALSE | C33: =IF(B33,LEFT(A33,10),C32) -> 2025-11-07 | D33: =A35 -> Perf (prev recs): | E33: =A36 -> SECU-B.ST N/A | F33: =A37 -> TELIA.ST N/A | G33: =A38 -> SAAB-B.ST N/A | H33: =A39 -> VOLV-B.ST N/A
A34: NOK – Nokia Corporation | B34: =ISNUMBER(LEFT(A34,4)+1-1) -> FALSE | C34: =IF(B34,LEFT(A34,10),C33) -> 2025-11-07 | D34: =A36 -> SECU-B.ST N/A | E34: =A37 -> TELIA.ST N/A | F34: =A38 -> SAAB-B.ST N/A | G34: =A39 -> VOLV-B.ST N/A | H34: =A40 -> ERIC-B.ST N/A
A35: Perf (prev recs): | B35: =ISNUMBER(LEFT(A35,4)+1-1) -> FALSE | C35: =IF(B35,LEFT(A35,10),C34) -> 2025-11-07 | D35: =A37 -> TELIA.ST N/A | E35: =A38 -> SAAB-B.ST N/A | F35: =A39 -> VOLV-B.ST N/A | G35: =A40 -> ERIC-B.ST N/A | H35: =A41 -> Avg N/A
A36: SECU-B.ST N/A | B36: =ISNUMBER(LEFT(A36,4)+1-1) -> FALSE | C36: =IF(B36,LEFT(A36,10),C35) -> 2025-11-07 | D36: =A38 -> SAAB-B.ST N/A | E36: =A39 -> VOLV-B.ST N/A | F36: =A40 -> ERIC-B.ST N/A | G36: =A41 -> Avg N/A | H36: =A42 -> S&P500 N/A
A37: TELIA.ST N/A | B37: =ISNUMBER(LEFT(A37,4)+1-1) -> FALSE | C37: =IF(B37,LEFT(A37,10),C36) -> 2025-11-07 | D37: =A39 -> VOLV-B.ST N/A | E37: =A40 -> ERIC-B.ST N/A | F37: =A41 -> Avg N/A | G37: =A42 -> S&P500 N/A | H37: =A43 -> 0
A38: SAAB-B.ST N/A | B38: =ISNUMBER(LEFT(A38,4)+1-1) -> FALSE | C38: =IF(B38,LEFT(A38,10),C37) -> 2025-11-07 | D38: =A40 -> ERIC-B.ST N/A | E38: =A41 -> Avg N/A | F38: =A42 -> S&P500 N/A | G38: =A43 -> 0 | H38: =A44 -> 2025-11-08 - Saturday
A39: VOLV-B.ST N/A | B39: =ISNUMBER(LEFT(A39,4)+1-1) -> FALSE | C39: =IF(B39,LEFT(A39,10),C38) -> 2025-11-07 | D39: =A41 -> Avg N/A | E39: =A42 -> S&P500 N/A | F39: =A43 -> 0 | G39: =A44 -> 2025-11-08 - Saturday | H39: =A45 -> Recs:
... A42: S&P500 N/A | B42: =ISNUMBER(LEFT(A42,4)+1-1) -> FALSE | C42: =IF(B42,LEFT(A42,10),C41) -> 2025-11-07 | D42: =A44 -> 2025-11-08 - Saturday | E42: =A45 -> Recs: | F42: =A46 -> SWEC-B.ST – Sweco AB | G42: =A47 -> ATCO-A.ST – Atlas Copco A | H42: =A48 -> HEXA-B.ST – Hexagon AB
B43: =ISNUMBER(LEFT(A43,4)+1-1) -> FALSE | C43: =IF(B43,LEFT(A43,10),C42) -> 2025-11-07 | D43: =A45 -> Recs: | E43: =A46 -> SWEC-B.ST – Sweco AB | F43: =A47 -> ATCO-A.ST – Atlas Copco A | G43: =A48 -> HEXA-B.ST – Hexagon AB | H43: =A49 -> INVE-B.ST – Investor AB
A44: 2025-11-08 - Saturday | B44: =ISNUMBER(LEFT(A44,4)+1-1) -> TRUE | C44: =IF(B44,LEFT(A44,10),C43) -> 2025-11-08 | D44: =A46 -> SWEC-B.ST – Sweco AB | E44: =A47 -> ATCO-A.ST – Atlas Copco A | F44: =A48 -> HEXA-B.ST – Hexagon AB | G44: =A49 -> INVE-B.ST – Investor AB | H44: =A50 -> SAND.ST – Sandvik AB
...

Sheet Clean
A1: String | B1: Rec 1 | C1: Rec 2 | D1: Rec 3 | E1: Rec 4 | F1: Rec 5
A2: ='Sum and Cleaner'!$A$2 -> 2025-11-05 - Wednesday | B2: NVDA – NVIDIA Corporation | C2: AAPL – Apple Inc. | D2: MSFT – Microsoft Corporation | E2: ERICb.ST – Telefonaktiebolaget LM Ericsson B | F2: BOL – The Boliden Company
A3: ='Sum and Cleaner'!$A$18 -> 2025-11-06 - Thursday | B3: SECU-B.ST – Securitas AB | C3: ERIC-B.ST – Ericsson B | D3: TELIA.ST – Telia Company | E3: SAAB-B.ST – Saab AB | F3: VOLV-B.ST – AB Volvo B
A4: ='Sum and Cleaner'!$A$28 -> 2025-11-07 - Friday | B4: TELIA.ST – Telia Company | C4: ERIC-B.ST – Ericsson B | D4: SAAB-B.ST – Saab AB | E4: VOLV-B.ST – AB Volvo B | F4: NOK – Nokia Corporation
A5: ='Sum and Cleaner'!$A$44 -> 2025-11-08 - Saturday | B5: SWEC-B.ST – Sweco AB | C5: ATCO-A.ST – Atlas Copco A | D5: HEXA-B.ST – Hexagon AB | E5: INVE-B.ST – Investor AB | F5: SAND.ST – Sandvik AB
A6: ='Sum and Cleaner'!$A$60 -> 2025-11-09 - Sunday | B6: SWEC-B.ST – Sweco AB | C6: ERIC-B.ST – Ericsson AB B | D6: SSAB-B.ST – SSAB AB B | E6: SHBa.ST – Handelsbanken AB | F6: INVE-B.ST – Investor AB B
A7: ='Sum and Cleaner'!$A$76 -> 2025-11-10 - Monday | B7: HEXA‑B.ST – Hexagon AB | C7: AZN – AstraZeneca plc | D7: EQTAB.ST – EQT AB | E7: SAABb.ST – Saab AB B | F7: BOL.ST – Boliden AB B
A8: ='Sum and Cleaner'!$A$91 -> 2025-10-23 - Thursday | B8: TSLA – Tesla Inc | C8: IBM – International Business Machines Corp | D8: NKE – Nike Inc | E8: SAND – Sandstorm Gold Ltd | F8: SEB_A – SEB AB
A9: ='Sum and Cleaner'!$A$107 -> 2025-10-24 - Friday | B9: TELIA – Telia Company AB | C9: PCELL – PowerCell Sweden AB | D9: SEB_A – SEB AB | E9: ERIC – Ericsson AB | F9: VOLV B – Volvo AB
A10: ='Sum and Cleaner'!$A$123 -> 2025-10-25 - Saturday | B10: AMD – Advanced Micro Devices Inc. | C10: MSFT – Microsoft Corp. | D10: SAND – Sandstorm Gold Ltd. | E10: ERIC – Ericsson AB | F10: TELIA – Telia Company AB
A11: ='Sum and Cleaner'!$A$139 -> 2025-10-26 - Sunday | B11: AAPL – Apple Inc. | C11: MSFT – Microsoft Corp. | D11: ERIC – Ericsson AB | E11: ADS – Adidas AG | F11: SAP – SAP SE
A12: ='Sum and Cleaner'!$A$155 -> 2025-10-27 - Monday | B12: AAPL – Apple Inc. | C12: MSFT – Microsoft Corp. | D12: TELIA – Telia Company AB | E12: NVIDIA – NVIDIA Corp. | F12: EXXON – Exxon Mobil Corp.
A13: ='Sum and Cleaner'!$A$171 -> 2025-10-28 - Tuesday | B13: AAPL – Apple Inc. | C13: MSFT – Microsoft Corp. | D13: GOOGL – Alphabet Inc. | E13: TSLA – Tesla Inc. | F13: TELIA – Telia Company AB
A14: ='Sum and Cleaner'!$A$181 -> 2025-11-11 - Tuesday | B14: AZN – AstraZeneca plc | C14: EQTAB.ST – EQT AB | D14: HEXA‑B.ST – Hexagon AB | E14: SAABb.ST – Saab AB B | F14: BOL.ST – Boliden AB
A15: ='Sum and Cleaner'!$A$197 -> 2025-11-12 - Wednesday | B15: AZN – AstraZeneca plc | C15: EQT.ST – EQT AB | D15: HEXA‑B.ST – Hexagon AB | E15: SAABb.ST – Saab AB B | F15: BOL.ST – Boliden AB
A16: ='Sum and Cleaner'!$A$213 -> 2025-11-13 - Thursday | B16: MSFT – Microsoft Corporation | C16: NVDA – NVIDIA Corporation | D16: SAAB B – Saab AB B | E16: BOL – Boliden AB | F16: SKF – SKF AB
A17: ='Sum and Cleaner'!$A$229 -> 2025-11-14 - Friday | B17: ERIC – Telefonaktiebolaget LM Ericsson | C17: MSFT – Microsoft Corporation | D17: NVDA – NVIDIA Corporation | E17: VOLV‑B.ST – AB Volvo B | F17: BOL.ST – Boliden AB
A18: ='Sum and Cleaner'!$A$245 -> 2025-11-15 - Saturday | B18: MSFT – Microsoft Corporation | C18: NVDA – NVIDIA Corporation | D18: APM – APM Terminals | E18: LACX – LACX Mining Corp | F18: KBH – KB Home
A19: ='Sum and Cleaner'!$A$261 -> 2025-11-16 - Sunday | B19: STOR B.ST – Storskogen Group AB Simply Wall St | C19: BOL.ST – Boliden AB Investing.com+1 | D19: MSFT – Microsoft Corporation | E19: NVDA – NVIDIA Corporation | F19: SSAB B.ST – SSAB AB Wikipedia
A20: ='Sum and Cleaner'!$A$277 -> 2025-11-17 - Monday | B20: AAPL – Apple Inc. | C20: CSCO – Cisco Systems Inc. | D20: CAT – Caterpillar Inc. | E20: BHP – BHP Group Ltd. | F20: SKLGF – SKF Group (Class B, Sweden)
A21: ='Sum and Cleaner'!$A$293 -> 2025-11-18 - Tuesday | B21: AAPL – Apple Inc. | C21: CSCO – Cisco Systems Inc. | D21: CAT – Caterpillar Inc.
A22: ='Sum and Cleaner'!$A$298 -> 2025-10-14 - Tuesday | B22: ERIC – Telefonaktiebolaget LM Ericsson | C22: SAAB-B.ST – Saab AB | D22: AZN.ST – AstraZeneca PLC | E22: AMD – Advanced Micro Devices, Inc. | F22: MP – MP Materials Corp.
A23: ='Sum and Cleaner'!$A$313 -> 2025-10-16 - Thursday | B23: VOLV-B.ST – Volvo | C23: NIBE-B.ST – Nibe Industrier | D23: SPOT – Spotify Technology | E23: TSLA – Tesla | F23: SHEL – Shell
A24: ='Sum and Cleaner'!$A$328 -> 2025-10-18 - Saturday | B24: ERIC – Ericsson | C24: SAND.ST – Sandvik | D24: AAPL – Apple | E24: RIO – Rio Tinto | F24: ORCL – Oracle
A25: ='Sum and Cleaner'!$A$343 -> 2025-10-19 - Sunday | B25: SKF-B.ST – SKF | C25: EVO.ST – Evolution AB | D25: MSFT – Microsoft | E25: NVO – Novo Nordisk | F25: BP – BP Plc
A26: ='Sum and Cleaner'!$A$358 -> 2025-10-21 - Tuesday | B26: AAPL – Apple | C26: TSLA – Tesla | D26: SHEL – Shell | E26: RIO – Rio Tinto | F26: ERIC – Ericsson
A27: ='Sum and Cleaner'!$A$373 -> 2025-10-22 - Wednesday | B27: SHB A – Handelsbanken | C27: SAABB – Saab AB | D27: SSAB A – SSAB AB | E27: AAPL – Apple Inc | F27: SHEL – Shell plc
A28: ='Sum and Cleaner'!$A$394 -> 2025‑10‑29 - Wednesday | B28: AAPL – Apple Inc. | C28: MSFT – Microsoft Corp. | D28: ASML – ASML Holding NV | E28: VOLV B – Volvo AB B‑share | F28: BABA – Alibaba Group Holding Ltd
A29: ='Sum and Cleaner'!$A$410 -> 2025-10-30 - Thursday | B29: TER – Teradyne Inc. | C29: CAT – Caterpillar Inc. | D29: W – Wayfair Inc. | E29: AVGO – Broadcom Inc. | F29: AMD – Advanced Micro Devices Inc.
A30: ='Sum and Cleaner'!$A$426 -> 2025-10-31 - Friday | B30: MSFT – Microsoft Corp. | C30: GOOGL – Alphabet Inc. | D30: VOLV B – Volvo AB Class B | E30: ASML – ASML Holding NV | F30: BA – Boeing Co.
A31: ='Sum and Cleaner'!$A$442 -> 2025-11-01 - Saturday | B31: AMZN – Amazon.com Inc | C31: AAPL – Apple Inc | D31: EQTAB.ST – EQT AB Class B | E31: CAT – Caterpillar Inc | F31: GOOGL – Alphabet Inc
A32: ='Sum and Cleaner'!$A$458 -> 2025-11-02 - Sunday | B32: EQTAB.ST – EQT AB Class B (Sweden) | C32: MSFT – Microsoft Corporation | D32: NVDA – NVIDIA Corporation | E32: JNJ – Johnson & Johnson | F32: XOM – Exxon Mobil Corporation
A33: ='Sum and Cleaner'!$A$474 -> 2025-11-03 - Monday | B33: SAAB B.ST – Saab AB | C33: SAVE.ST – Nordnet AB | D33: EQTAB.ST – EQT AB Class B | E33: ERIC B.ST – Ericsson AB | F33: AAPL – Apple Inc
A34: ='Sum and Cleaner'!$A$490 -> 2025-11-04 - Tuesday | B34: EQTAB.ST – EQT AB Class B | C34: NVDA – NVIDIA Corporation | D34: VRTX – Vertex Pharmaceuticals | E34: DELL – Dell Technologies Inc. | F34: TELIA.ST – Telia Company
A35: ='Sum and Cleaner'!$A$516 -> 2025-11-19 - Wednesday | B35: CSCO – Cisco Systems Inc. | C35: AAPL – Apple Inc. | D35: CAT – Caterpillar Inc. | E35: BHP – BHP Group Ltd. | F35: SKFB.ST – SKF AB (Sweden)
A36: ='Sum and Cleaner'!$A$531 -> 2025-11-19 - Wednesday | B36: NVDA – NVIDIA Corp | C36: ERIC – Telefonaktiebolaget LM Ericsson | D36: VOLV-B.ST – AB Volvo (publ) B | E36: AZN.ST – AstraZeneca PLC | F36: VOLCAR-B.ST – Volvo Car AB (publ.)
A37: ='Sum and Cleaner'!$A$547 -> 2025-11-20 - Thursday | B37: NVDA – NVIDIA Corp | C37: AMD – Advanced Micro Devices Inc. | D37: WMT – Walmart Inc. | E37: SYNSAM.ST – Synsam AB (publ) | F37: HUFV-A.ST – Hufvudstaden AB (publ)
A38: ='Sum and Cleaner'!$A$563 -> 2025-11-21 - Friday | B38: NVDA – NVIDIA Corporation | C38: ERIC – Telefonaktiebolaget LM Ericsson | D38: WMT – Walmart Inc. | E38: TEL – Telia Company AB | F38: TAK – Takkt AG
A39: ='Sum and Cleaner'!$A$579 -> 2025-11-22 - Saturday | B39: AAPL – Apple Inc. | C39: SAP – SAP SE | D39: SAND.ST – Sandvik AB | E39: ORSTED.CO – Ørsted A/S | F39: TSLA – Tesla Inc.
A40: ='Sum and Cleaner'!$A$595 -> 2025-11-23 - Sunday | B40: SAAB B – Saab AB | C40: WBD – Warner Bros. Discovery, Inc. | D40: COST – Costco Wholesale Corporation | E40: LRCX – Lam Research Corporation | F40: ASML – ASML Holding N.V.
...

Sheet List to fetch
A1: Rec 1 | B1: Ticker
A2: NVDA – NVIDIA Corporation | B2: =LEFT(A2,6) -> NVDA –
A3: SECU-B.ST – Securitas AB | B3: =LEFT(A3,6) -> SECU-B
A4: TELIA.ST – Telia Company | B4: =LEFT(A4,6) -> TELIA.
A5: SWEC-B.ST – Sweco AB | B5: =LEFT(A5,6) -> SWEC-B
A6: SWEC-B.ST – Sweco AB | B6: =LEFT(A6,6) -> SWEC-B
A7: HEXA‑B.ST – Hexagon AB | B7: =LEFT(A7,6) -> HEXA‑B
A8: TSLA – Tesla Inc | B8: =LEFT(A8,6) -> TSLA –
A9: TELIA – Telia Company AB | B9: =LEFT(A9,6) -> TELIA
A10: AMD – Advanced Micro Devices Inc. | B10: =LEFT(A10,6) -> AMD –
A11: AAPL – Apple Inc. | B11: =LEFT(A11,6) -> AAPL –
A12: AAPL – Apple Inc. | B12: =LEFT(A12,6) -> AAPL –
A13: AAPL – Apple Inc. | B13: =LEFT(A13,6) -> AAPL –
... A230: CRH – CRH plc (S&P 500 inclusion announcement lifting name) Barron's | B230: =LEFT(A230,6) -> CRH –

Sheet changed on 161225
A1: For a short term trade, to be opened in the morning and closed at end of day, search for the latest major global news. Recommend EXACTLY 5 BUY tickers for short-term trade based on whatever you think is relevant. add very short reasoning after the recommendation.
A3: Start with one line containing the local date and day of week in Stockholm time formatted exactly as:
A4: YYYY-MM-DD / HH:MM - Monday
A6: Recs:
A7: TICKER – Company (short reasoning)
A8: TICKER – Company (short reasoning)
A9: TICKER – Company (short reasoning)
A10: TICKER – Company (short reasoning)
A11: TICKER – Company (short reasoning)
A14: Used to be: FRESH CATALYSTS AND MOMENTUM

Sheet 2026-01-04 to 2026-05-19 longeq
A1: ChatGPT | B1: longeq
B2: longeq
B3: longeq
A4: Updated memory | B4: longeq
B5: longeq
A6: They are 0 because no price data was retrieved for those Indian tickers. | B6: longeq
A7: This happens for one of three mechanical reasons: | B7: longeq
B8: longeq
A9: 1. They do not trade on US or EU exchanges and the fetch layer used here does not return NSE/BSE closes. | B9: longeq
A10: 2. On non-trading days (weekend or holiday), the system falls back to “no change” when no prior close is available. | B10: longeq
A11: 3. Without two independent price sources for those symbols, the return calculator fails and defaults to 0 rather than fabricate numbers. | B11: longeq
B12: longeq
A13: This is a data-availability issue, not a market-movement result. | B13: longeq
B14: longeq
A15: 2025-12-10 / 08:16 - Wednesday | B15: longeq
B16: longeq
A17: Recs: | B17: longeq
A18: NVDA – Nvidia | B18: longeq
A19: ORCL – Oracle | B19: longeq
A20: SHEL – Shell | B20: longeq
A21: BHP – BHP Group | B21: longeq
A22: RIO – Rio Tinto | B22: longeq
B23: longeq
A24: Prev days return S&P500 +0.00% | B24: longeq
B25: longeq
A26: 2025‑12‑11 / 08:15 - Thursday | B26: longeq
B27: longeq
A28: Recs: | B28: longeq
A29: GEV - GE Vernova Inc (breakout after strong catalyst and technical momentum) | B29: longeq
A30: PLTR - Palantir Technologies (recent contract win and positive flow) | B30: longeq
A31: SATS - EchoStar Corp (premarket strength and sector interest) | B31: longeq
A32: AVTR - Avantor Inc (premarket gains signaling momentum) | B32: longeq
A33: FSLR - First Solar (sector news on project supply momentum) | B33: longeq
B34: longeq
A35: Prev days return S&P500 +0.67% | B35: longeq
B36: longeq
A37: 2025‑12‑12 / 08:15 - Friday | B37: longeq
B38: longeq
A39: Recs: | B39: longeq
A40: NVDA - Nvidia (momentum from AI demand and trading strength) | B40: longeq
...

Sheet 2025-12-05 to 2026-05-19 longal
A1: ChatGPT | B1: LONGALL
B2: LONGALL
B3: LONGALL
A4: For a short term trade, to be opened in the morning and closed at end of day, search for the latest major global news. Recommend EXACTLY 5 LONG instruments for short-term trade based on whatever you think is relevant. The investment universe may include equities, equity indices, commodities, FX, rates, and their liquid derivatives (futures, options, or major ETFs). Add very short reasoning after each recommendation. Start with one line containing the local date and day of week in Stockholm time formatted exactly as: YYYY-MM-DD / HH:MM - Monday Recs: SYMBOL – Instrument name (short reasoning) SYMBOL – Instrument name (short reasoning) SYMBOL – Instrument name (short reasoning) SYMBOL – Instrument name (short reasoning) SYMBOL – Instrument name (short reasoning) | B4: LONGALL
B5: LONGALL
A6: 2026-01-05 / 07:00 - Monday | B6: LONGALL
B7: LONGALL
A8: Recs: | B8: LONGALL
A9: SPY – major US equity ETF likely to benefit from early-year recovery sentiment after Santa Claus rally and dip bounce | B9: LONGALL
A10: BTCUSD – Bitcoin showing breakout momentum above recent highs suggesting continuation into new week | B10: LONGALL
A11: FTSE – UK index breaking key level reflecting strong European risk appetite and rate cut expectations | B11: LONGALL
A12: CL1 – WTI crude futures likely supported by geopolitical risk and supply dynamics referenced in global markets news | B12: LONGALL
A13: DAX – German equity index poised to extend gains on eurozone growth and dovish central bank expectations | B13: LONGALL
B14: LONGALL
A15: set this up as a daily task at 8:15 | B15: LONGALL
A16: Updated memory | B16: LONGALL
A17: Generate daily long trade ideas | B17: LONGALL
A18: Daily at 3:30 AM | B18: LONGALL
A19: Daily task scheduled. Runs every day at 08:15 Stockholm time. | B19: LONGALL
B20: LONGALL
A21: 2026‑01‑05 / 08:16 - Monday | B21: LONGALL
B22: LONGALL
A23: Recs: | B23: LONGALL
A24: NIKKEI – Japan Nikkei 225 Index (Asia stocks rally on resilience despite geopolitical stress) | B24: LONGALL
A25: HSI – Hang Seng Index (Chinese market strength above key level on optimism) | B25: LONGALL
A26: XAUUSD – Gold Spot (safe haven demand rising amid geopolitical risk) | B26: LONGALL
A27: AUDUSD – AUD/USD FX (AUD holding near uptrend support as US dollar capped) | B27: LONGALL
A28: BTCUSD – Bitcoin (crypto showing strength with broader risk asset gains) | B28: LONGALL
B29: LONGALL
A30: 2026‑01‑06 / 08:15 - Tuesday | B30: LONGALL
B31: LONGALL
A32: Recs: | B32: LONGALL
A33: DJI - Dow Jones Industrial Average futures (global equities rally led by energy and banks) | B33: LONGALL
A34: FTSE - FTSE 100 Index (defence and mining strength on geopolitical risk) | B34: LONGALL
A35: CL1 - WTI Crude Oil futures (energy stocks strong post‑Venezuela news) | B35: LONGALL
A36: XAU - Gold Spot (safe‑haven asset rising on uncertainty) | B36: LONGALL
A37: USDJPY - USD/JPY FX (dollar weakness narrative may fuel carry and risk flows) | B37: LONGALL
B38: LONGALL
A39: 2026-01-07 / 08:15 - Monday | B39: LONGALL
B40: LONGALL
...

Sheet 2026-01-04 to 2026-05-19 short
A1: ChatGPT | B1: SHORT
B2: SHORT
B3: SHORT
A4: For a short term trade, to be opened in the morning and closed at end of day, search for the latest major global news. Recommend EXACTLY 5 SHORT instruments for short-term trade based on whatever you think is relevant. The investment universe may include equities, equity indices, commodities, FX, rates, and their liquid derivatives (futures, options, or major ETFs). Add very short reasoning after each recommendation. Start with one line containing the local date and day of week in Stockholm time formatted exactly as: YYYY-MM-DD / HH:MM - Monday Recs: SYMBOL – Instrument name (short reasoning) SYMBOL – Instrument name (short reasoning) SYMBOL – Instrument name (short reasoning) SYMBOL – Instrument name (short reasoning) SYMBOL – Instrument name (short reasoning) | B4: SHORT
B5: SHORT
A6: 2026-01-04 / 08:00 - Sunday | B6: SHORT
B7: SHORT
A8: Recs: | B8: SHORT
A9: ES00 (E-mini S&P 500 futures) – risk-off pressure from geopolitical shocks (Venezuela capture) and mixed global equities suggests downside bias. | B9: SHORT
A10: WTI (Crude Oil futures) – short-term supply disruption risk priced in but directional uncertainty and potential pullback after recent surge. | B10: SHORT
A11: DXY (US Dollar Index) – prospect of Fed rate cuts and dollar weakness into 2026 could cause short-term corrective leg lower. | B11: SHORT
A12: XLF (Financial Select Sector SPDR ETF) – activist investor pressure and bank sector stress elevate short downside risk. | B12: SHORT
A13: NQ00 (E-mini Nasdaq 100 futures) – tech softness from profit-taking after 2025 gains implies potential intraday pullback. | B13: SHORT
B14: SHORT
A15: set this up as a daily task at 8:15 | B15: SHORT
A16: Generate short trade shorts | B16: SHORT
A17: Daily at 3:30 PM | B17: SHORT
A18: Task scheduled. Daily at 08:15 Stockholm time. | B18: SHORT
B19: SHORT
A20: 2026‑01‑05 / 08:15 - Monday | B20: SHORT
B21: SHORT
A22: SPY - broad US equity risk off, profit‑taking heavy after long run, valuation stretched. | B22: SHORT
A23: CL_F - crude oil futures weakening on supply expectations and technical pressure. | B23: SHORT
A24: XAGUSD - silver peaked then pulled back, technicals point to correction. | B24: SHORT
A25: USDJPY - FX showing US dollar capped and mixed risk appetite - short yen weakness. | B25: SHORT
A26: VIX - volatility index extremely low with asymmetric upside risk, anticipate repricing. | B26: SHORT
B27: SHORT
A28: isn't vix then should be Long if low | B28: SHORT
B29: SHORT
A30: Correct. | B30: SHORT
B31: SHORT
A32: If VIX is low, the directional trade is LONG VIX, not short. | B32: SHORT
A33: Low implied volatility implies asymmetric upside risk and mean reversion favors expansion. | B33: SHORT
A34: Shorting VIX only makes sense after a volatility spike, not at compressed levels. | B34: SHORT
B35: SHORT
A36: Conclusion: VIX was misclassified. A low-VIX regime invalidates it as a short candidate. | B36: SHORT
B37: SHORT
A38: please reiterate if there is any wrong "shorts" in last recommendation | B38: SHORT
A39: Updated memories | B39: SHORT
B40: SHORT
...

Sheet Sheet6
A1: {=_xlfn.VSTACK(_xlfn._xlws.FILTER('2026-01-04 to 2026-05-19 longeq'!B:B,ISBLANK('2026-01-04 to 2026-05-19 longeq'!$A:$A)=FALSE,""),_xlfn._xlws.FILTER('2025-12-05 to 2026-05-19 longal'!B:B,ISBLANK('2025-12-05 to 2026-05-19 longal'!$A:$A)=FALSE,""),_xlfn._xlws.FILTER('2026-01-04 to 2026-05-19 short'!B:B,ISBLANK('2025-12-05 to 2026-05-19 longal'!$A:$A)=FALSE,""))} -> longeq | B1: {=_xlfn.VSTACK(_xlfn._xlws.FILTER('2026-01-04 to 2026-05-19 longeq'!A:A,ISBLANK('2026-01-04 to 2026-05-19 longeq'!$A:$A)=FALSE,""),_xlfn._xlws.FILTER('2025-12-05 to 2026-05-19 longal'!A:A,ISBLANK('2025-12-05 to 2026-05-19 longal'!$A:$A)=FALSE,""),_xlfn._xlws.FILTER('2026-01-04 to 2026-05-19 short'!A:A,ISBLANK('2025-12-05 to 2026-05-19 longal'!$A:$A)=FALSE,""))} -> ChatGPT | C1: Is date? | D1: Date
A2: longeq | B2: Updated memory | C2: =ISNUMBER(LEFT(B2,4)+1-1) -> FALSE | D2: =IF(C2,LEFT(B2,10),D1)+1-1 -> #VALUE!
A3: longeq | B3: They are 0 because no price data was retrieved for those Indian tickers. | C3: =ISNUMBER(LEFT(B3,4)+1-1) -> FALSE | D3: =IF(C3,LEFT(B3,10),D2)+1-1 -> #VALUE!
A4: longeq | B4: This happens for one of three mechanical reasons: | C4: =ISNUMBER(LEFT(B4,4)+1-1) -> FALSE | D4: =IF(C4,LEFT(B4,10),D3)+1-1 -> #VALUE!
A5: longeq | B5: 1. They do not trade on US or EU exchanges and the fetch layer used here does not return NSE/BSE closes. | C5: =ISNUMBER(LEFT(B5,4)+1-1) -> FALSE | D5: =IF(C5,LEFT(B5,10),D4)+1-1 -> #VALUE!
A6: longeq | B6: 2. On non-trading days (weekend or holiday), the system falls back to “no change” when no prior close is available. | C6: =ISNUMBER(LEFT(B6,4)+1-1) -> FALSE | D6: =IF(C6,LEFT(B6,10),D5)+1-1 -> #VALUE!
A7: longeq | B7: 3. Without two independent price sources for those symbols, the return calculator fails and defaults to 0 rather than fabricate numbers. | C7: =ISNUMBER(LEFT(B7,4)+1-1) -> FALSE | D7: =IF(C7,LEFT(B7,10),D6)+1-1 -> #VALUE!
A8: longeq | B8: This is a data-availability issue, not a market-movement result. | C8: =ISNUMBER(LEFT(B8,4)+1-1) -> FALSE | D8: =IF(C8,LEFT(B8,10),D7)+1-1 -> #VALUE!
A9: longeq | B9: 2025-12-10 / 08:16 - Wednesday | C9: =ISNUMBER(LEFT(B9,4)+1-1) -> TRUE | D9: =IF(C9,LEFT(B9,10),D8)+1-1 -> 46001
A10: longeq | B10: Recs: | C10: =ISNUMBER(LEFT(B10,4)+1-1) -> FALSE | D10: =IF(C10,LEFT(B10,10),D9)+1-1 -> 46001
A11: longeq | B11: NVDA – Nvidia | C11: =ISNUMBER(LEFT(B11,4)+1-1) -> FALSE | D11: =IF(C11,LEFT(B11,10),D10)+1-1 -> 46001
A12: longeq | B12: ORCL – Oracle | C12: =ISNUMBER(LEFT(B12,4)+1-1) -> FALSE | D12: =IF(C12,LEFT(B12,10),D11)+1-1 -> 46001
A13: longeq | B13: SHEL – Shell | C13: =ISNUMBER(LEFT(B13,4)+1-1) -> FALSE | D13: =IF(C13,LEFT(B13,10),D12)+1-1 -> 46001
... A40: longeq | B40: Prev days return S&P500 ‑1.07% | C40: =ISNUMBER(LEFT(B40,4)+1-1) -> FALSE | D40: =IF(C40,LEFT(B40,10),D39)+1-1 -> #VALUE!
A41: longeq | B41: 2025‑12‑14 / 08:15 - Sunday | C41: =ISNUMBER(LEFT(B41,4)+1-1) -> TRUE | D41: =IF(C41,LEFT(B41,10),D40) -> 2025‑12‑14 | E41: 2025‑12‑14
A42: longeq | B42: Recs: | C42: =ISNUMBER(LEFT(B42,4)+1-1) -> FALSE | D42: =IF(C42,LEFT(B42,10),D41)+1-1 -> #VALUE!
A43: longeq | B43: TSLA - Tesla Inc (momentum from positive technical and product catalysts) | C43: =ISNUMBER(LEFT(B43,4)+1-1) -> FALSE | D43: =IF(C43,LEFT(B43,10),D42)+1-1 -> #VALUE!
A44: longeq | B44: GE - GE Aerospace (industrial strength and near buy point on recent flow) | C44: =ISNUMBER(LEFT(B44,4)+1-1) -> FALSE | D44: =IF(C44,LEFT(B44,10),D43)+1-1 -> #VALUE!
A45: longeq | B45: LLY - Eli Lilly & Co (healthcare resilience and data‑driven upside) | C45: =ISNUMBER(LEFT(B45,4)+1-1) -> FALSE | D45: =IF(C45,LEFT(B45,10),D44)+1-1 -> #VALUE!
A46: longeq | B46: JPM - JPMorgan Chase & Co (financials strength amid rotation) | C46: =ISNUMBER(LEFT(B46,4)+1-1) -> FALSE | D46: =IF(C46,LEFT(B46,10),D45)+1-1 -> #VALUE!
A47: longeq | B47: WBD - Warner Bros Discovery (takeover bid driving elevated activity) | C47: =ISNUMBER(LEFT(B47,4)+1-1) -> FALSE | D47: =IF(C47,LEFT(B47,10),D46)+1-1 -> #VALUE!
A48: longeq | B48: Prev days return S&P500 ‑1.07% | C48: =ISNUMBER(LEFT(B48,4)+1-1) -> FALSE | D48: =IF(C48,LEFT(B48,10),D47)+1-1 -> #VALUE!
A49: longeq | B49: 2025-12-15 / 08:15 - Monday | C49: =ISNUMBER(LEFT(B49,4)+1-1) -> TRUE | D49: =IF(C49,LEFT(B49,10),D48)+1-1 -> 46006
A50: longeq | B50: Recs: | C50: =ISNUMBER(LEFT(B50,4)+1-1) -> FALSE | D50: =IF(C50,LEFT(B50,10),D49)+1-1 -> 46006
A51: longeq | B51: BAC – Bank of America Corp (record highs and Fed rate cut narrative driving financial flows) | C51: =ISNUMBER(LEFT(B51,4)+1-1) -> FALSE | D51: =IF(C51,LEFT(B51,10),D50)+1-1 -> 46006
A52: longeq | B52: WBD – Warner Bros Discovery (takeover battle boosting share activity) | C52: =ISNUMBER(LEFT(B52,4)+1-1) -> FALSE | D52: =IF(C52,LEFT(B52,10),D51)+1-1 -> 46006
A53: longeq | B53: IBM – International Business Machines (acquisition news lifting tech sentiment) | C53: =ISNUMBER(LEFT(B53,4)+1-1) -> FALSE | D53: =IF(C53,LEFT(B53,10),D52)+1-1 -> 46006
... A603: SHORT | B603: Task scheduled. Daily at 08:15 Stockholm time. | C603: =ISNUMBER(LEFT(B603,4)+1-1) -> FALSE | D603: =IF(C603,LEFT(B603,10),D602)+1-1 -> 46026
A604: SHORT | B604: 0 | C604: =ISNUMBER(LEFT(B604,4)+1-1) -> TRUE | D604: =IF(C604,LEFT(B604,10),D603)+1-1 -> 0
A605: SHORT | B605: 0 | C605: =ISNUMBER(LEFT(B605,4)+1-1) -> TRUE | D605: =IF(C605,LEFT(B605,10),D604)+1-1 -> 0
A606: SHORT | B606: CL_F - crude oil futures weakening on supply expectations and technical pressure. | C606: =ISNUMBER(LEFT(B606,4)+1-1) -> FALSE | D606: =IF(C606,LEFT(B606,10),D605)+1-1 -> 0
A607: SHORT | B607: XAGUSD - silver peaked then pulled back, technicals point to correction. | C607: =ISNUMBER(LEFT(B607,4)+1-1) -> FALSE | D607: =IF(C607,LEFT(B607,10),D606)+1-1 -> 0
A608: SHORT | B608: USDJPY - FX showing US dollar capped and mixed risk appetite - short yen weakness. | C608: =ISNUMBER(LEFT(B608,4)+1-1) -> FALSE | D608: =IF(C608,LEFT(B608,10),D607)+1-1 -> 0
A609: SHORT | B609: VIX - volatility index extremely low with asymmetric upside risk, anticipate repricing. | C609: =ISNUMBER(LEFT(B609,4)+1-1) -> FALSE | D609: =IF(C609,LEFT(B609,10),D608)+1-1 -> 0
A610: SHORT | B610: 0 | C610: =ISNUMBER(LEFT(B610,4)+1-1) -> TRUE | D610: =IF(C610,LEFT(B610,10),D609)+1-1 -> 0
A611: SHORT | B611: isn't vix then should be Long if low | C611: =ISNUMBER(LEFT(B611,4)+1-1) -> FALSE | D611: =IF(C611,LEFT(B611,10),D610)+1-1 -> 0
A612: SHORT | B612: Correct. | C612: =ISNUMBER(LEFT(B612,4)+1-1) -> FALSE | D612: =IF(C612,LEFT(B612,10),D611)+1-1 -> 0
A613: SHORT | B613: If VIX is low, the directional trade is LONG VIX, not short. | C613: =ISNUMBER(LEFT(B613,4)+1-1) -> FALSE | D613: =IF(C613,LEFT(B613,10),D612)+1-1 -> 0
A614: SHORT | B614: Low implied volatility implies asymmetric upside risk and mean reversion favors expansion. | C614: =ISNUMBER(LEFT(B614,4)+1-1) -> FALSE | D614: =IF(C614,LEFT(B614,10),D613)+1-1 -> 0
A615: SHORT | B615: Shorting VIX only makes sense after a volatility spike, not at compressed levels. | C615: =ISNUMBER(LEFT(B615,4)+1-1) -> FALSE | D615: =IF(C615,LEFT(B615,10),D614)+1-1 -> 0
...

Sheet Sheet5
A1: Is date? | B1: TRUE
A3: Count of Date | B3: Column Labels
A4: Row Labels | B4: longall | C4: longeq | D4: short | E4: Grand Total
A5: #VALUE! | B5: 8 | D5: 17 | E5: 25
A6: 45995 | C6: 1 | E6: 1
A7: 45996 | C7: 2 | E7: 2
A8: 46026 | D8: 1 | E8: 1
A9: 46027 | B9: 1 | E9: 1
A10: 46029 | B10: 1 | E10: 1
A11: 46031 | B11: 1 | E11: 1
A12: 46032 | B12: 1 | E12: 1
A13: 46033 | B13: 1 | E13: 1
A14: 46034 | D14: 2 | E14: 2
A15: 46037 | B15: 1 | E15: 1
A16: 46038 | B16: 1 | E16: 1
A17: 46040 | B17: 1 | D17: 1 | E17: 2
A18: 46041 | B18: 2 | D18: 1 | E18: 3
A19: 46042 | B19: 1 | D19: 1 | E19: 2
A20: 46043 | D20: 1 | E20: 1
A21: 46044 | B21: 1 | E21: 1
A22: 46046 | B22: 1 | E22: 1
A23: 46047 | B23: 1 | E23: 1
A24: 46048 | B24: 1 | E24: 1
A25: 46050 | D25: 1 | E25: 1
A26: 46051 | D26: 1 | E26: 1
A27: 46160 | B27: 1 | C27: 1 | D27: 1 | E27: 3
A28: 46161 | B28: 1 | C28: 1 | D28: 1 | E28: 3
A29: Grand Total | B29: 25 | C29: 5 | D29: 28 | E29: 58

Sheet threesheets merge
A1: disable? | B1: strategy | D1: Is date? | E1: Date | F1: Rec 1 | G1: Rec 2 | H1: Rec 3 | I1: Rec 4 | J1: Rec 5
B2: longeq | C2: 2025-12-04 / 14:05 - Thursday | D2: =ISNUMBER(LEFT(C2,4)+1-1) -> TRUE | E2: =IF(D2,LEFT(C2,10),E1)+1-1 -> 45995 | F2: =C4 -> Recs: | G2: =C5 -> MRVL – Marvell Technology, Inc. | H2: =C6 -> RIO – Rio Tinto plc | I2: =C7 -> STLA – Stellantis N.V. | J2: =C8 -> TD – The Toronto-Dominion Bank
B3: longeq | D3: =ISNUMBER(LEFT(C3,4)+1-1) -> FALSE | E3: =IF(D3,LEFT(C3,10),E2)+1-1 -> 45995 | F3: =C5 -> MRVL – Marvell Technology, Inc. | G3: =C6 -> RIO – Rio Tinto plc | H3: =C7 -> STLA – Stellantis N.V. | I3: =C8 -> TD – The Toronto-Dominion Bank | J3: =C9 -> CRDO – Credo Technology Group Holding Ltd.
B4: longeq | C4: Recs: | D4: =ISNUMBER(LEFT(C4,4)+1-1) -> FALSE | E4: =IF(D4,LEFT(C4,10),E3)+1-1 -> 45995 | F4: =C6 -> RIO – Rio Tinto plc | G4: =C7 -> STLA – Stellantis N.V. | H4: =C8 -> TD – The Toronto-Dominion Bank | I4: =C9 -> CRDO – Credo Technology Group Holding Ltd. | J4: =C10 -> 0
B5: longeq | C5: MRVL – Marvell Technology, Inc. | D5: =ISNUMBER(LEFT(C5,4)+1-1) -> FALSE | E5: =IF(D5,LEFT(C5,10),E4)+1-1 -> 45995 | F5: =C7 -> STLA – Stellantis N.V. | G5: =C8 -> TD – The Toronto-Dominion Bank | H5: =C9 -> CRDO – Credo Technology Group Holding Ltd. | I5: =C10 -> 0 | J5: =C11 -> Prev days return S&P500 +0.30%
B6: longeq | C6: RIO – Rio Tinto plc | D6: =ISNUMBER(LEFT(C6,4)+1-1) -> FALSE | E6: =IF(D6,LEFT(C6,10),E5)+1-1 -> 45995 | F6: =C8 -> TD – The Toronto-Dominion Bank | G6: =C9 -> CRDO – Credo Technology Group Holding Ltd. | H6: =C10 -> 0 | I6: =C11 -> Prev days return S&P500 +0.30% | J6: =C12 -> 0
B7: longeq | C7: STLA – Stellantis N.V. | D7: =ISNUMBER(LEFT(C7,4)+1-1) -> FALSE | E7: =IF(D7,LEFT(C7,10),E6)+1-1 -> 45995 | F7: =C9 -> CRDO – Credo Technology Group Holding Ltd. | G7: =C10 -> 0 | H7: =C11 -> Prev days return S&P500 +0.30% | I7: =C12 -> 0 | J7: =C13 -> please set this up as a task.
B8: longeq | C8: TD – The Toronto-Dominion Bank | D8: =ISNUMBER(LEFT(C8,4)+1-1) -> FALSE | E8: =IF(D8,LEFT(C8,10),E7)+1-1 -> 45995 | F8: =C10 -> 0 | G8: =C11 -> Prev days return S&P500 +0.30% | H8: =C12 -> 0 | I8: =C13 -> please set this up as a task. | J8: =C14 -> Produce daily short-term EQ trade recommendations
B9: longeq | C9: CRDO – Credo Technology Group Holding Ltd. | D9: =ISNUMBER(LEFT(C9,4)+1-1) -> FALSE | E9: =IF(D9,LEFT(C9,10),E8)+1-1 -> 45995 | F9: =C11 -> Prev days return S&P500 +0.30% | G9: =C12 -> 0 | H9: =C13 -> please set this up as a task. | I9: =C14 -> Produce daily short-term EQ trade recommendations | J9: =C15 -> Daily at 3:30 PM
B10: longeq | D10: =ISNUMBER(LEFT(C10,4)+1-1) -> FALSE | E10: =IF(D10,LEFT(C10,10),E9)+1-1 -> 45995 | F10: =C12 -> 0 | G10: =C13 -> please set this up as a task. | H10: =C14 -> Produce daily short-term EQ trade recommendations | I10: =C15 -> Daily at 3:30 PM | J10: =C16 -> 0
B11: longeq | C11: Prev days return S&P500 +0.30% | D11: =ISNUMBER(LEFT(C11,4)+1-1) -> FALSE | E11: =IF(D11,LEFT(C11,10),E10)+1-1 -> 45995 | F11: =C13 -> please set this up as a task. | G11: =C14 -> Produce daily short-term EQ trade recommendations | H11: =C15 -> Daily at 3:30 PM | I11: =C16 -> 0 | J11: =C17 -> Set.
B12: longeq | D12: =ISNUMBER(LEFT(C12,4)+1-1) -> FALSE | E12: =IF(D12,LEFT(C12,10),E11)+1-1 -> 45995 | F12: =C14 -> Produce daily short-term EQ trade recommendations | G12: =C15 -> Daily at 3:30 PM | H12: =C16 -> 0 | I12: =C17 -> Set. | J12: =C18 -> 0
B13: longeq | C13: please set this up as a task. | D13: =ISNUMBER(LEFT(C13,4)+1-1) -> FALSE | E13: =IF(D13,LEFT(C13,10),E12)+1-1 -> 45995 | F13: =C15 -> Daily at 3:30 PM | G13: =C16 -> 0 | H13: =C17 -> Set. | I13: =C18 -> 0 | J13: =C19 -> thanks! Please re-run as a test
B14: longeq | C14: Produce daily short-term EQ trade recommendations | D14: =ISNUMBER(LEFT(C14,4)+1-1) -> FALSE | E14: =IF(D14,LEFT(C14,10),E13)+1-1 -> 45995 | F14: =C16 -> 0 | G14: =C17 -> Set. | H14: =C18 -> 0 | I14: =C19 -> thanks! Please re-run as a test | J14: =C20 -> 0
B15: longeq | C15: Daily at 3:30 PM | D15: =ISNUMBER(LEFT(C15,4)+1-1) -> FALSE | E15: =IF(D15,LEFT(C15,10),E14)+1-1 -> 45995 | F15: =C17 -> Set. | G15: =C18 -> 0 | H15: =C19 -> thanks! Please re-run as a test | I15: =C20 -> 0 | J15: =C21 -> 2025-12-05 / 09:00 - Friday
B16: longeq | D16: =ISNUMBER(LEFT(C16,4)+1-1) -> FALSE | E16: =IF(D16,LEFT(C16,10),E15)+1-1 -> 45995 | F16: =C18 -> 0 | G16: =C19 -> thanks! Please re-run as a test | H16: =C20 -> 0 | I16: =C21 -> 2025-12-05 / 09:00 - Friday | J16: =C22 -> 0
B17: longeq | C17: Set. | D17: =ISNUMBER(LEFT(C17,4)+1-1) -> FALSE | E17: =IF(D17,LEFT(C17,10),E16)+1-1 -> 45995 | F17: =C19 -> thanks! Please re-run as a test | G17: =C20 -> 0 | H17: =C21 -> 2025-12-05 / 09:00 - Friday | I17: =C22 -> 0 | J17: =C23 -> Recs:
B18: longeq | D18: =ISNUMBER(LEFT(C18,4)+1-1) -> FALSE | E18: =IF(D18,LEFT(C18,10),E17)+1-1 -> 45995 | F18: =C20 -> 0 | G18: =C21 -> 2025-12-05 / 09:00 - Friday | H18: =C22 -> 0 | I18: =C23 -> Recs: | J18: =C24 -> XOM – Exxon Mobil Corporation
B19: longeq | C19: thanks! Please re-run as a test | D19: =ISNUMBER(LEFT(C19,4)+1-1) -> FALSE | E19: =IF(D19,LEFT(C19,10),E18)+1-1 -> 45995 | F19: =C21 -> 2025-12-05 / 09:00 - Friday | G19: =C22 -> 0 | H19: =C23 -> Recs: | I19: =C24 -> XOM – Exxon Mobil Corporation | J19: =C25 -> FCX – Freeport-McMoRan Inc.
B20: longeq | D20: =ISNUMBER(LEFT(C20,4)+1-1) -> FALSE | E20: =IF(D20,LEFT(C20,10),E19)+1-1 -> 45995 | F20: =C22 -> 0 | G20: =C23 -> Recs: | H20: =C24 -> XOM – Exxon Mobil Corporation | I20: =C25 -> FCX – Freeport-McMoRan Inc. | J20: =C26 -> AIR – Airbus SE
B21: longeq | C21: 2025-12-05 / 09:00 - Friday | D21: =ISNUMBER(LEFT(C21,4)+1-1) -> TRUE | E21: =IF(D21,LEFT(C21,10),E20)+1-1 -> 45996 | F21: =C23 -> Recs: | G21: =C24 -> XOM – Exxon Mobil Corporation | H21: =C25 -> FCX – Freeport-McMoRan Inc. | I21: =C26 -> AIR – Airbus SE | J21: =C27 -> BTI – British American Tobacco plc
B22: longeq | D22: =ISNUMBER(LEFT(C22,4)+1-1) -> FALSE | E22: =IF(D22,LEFT(C22,10),E21)+1-1 -> 45996 | F22: =C24 -> XOM – Exxon Mobil Corporation | G22: =C25 -> FCX – Freeport-McMoRan Inc. | H22: =C26 -> AIR – Airbus SE | I22: =C27 -> BTI – British American Tobacco plc | J22: =C28 -> BHP – BHP Group Ltd.
B23: longeq | C23: Recs: | D23: =ISNUMBER(LEFT(C23,4)+1-1) -> FALSE | E23: =IF(D23,LEFT(C23,10),E22)+1-1 -> 45996 | F23: =C25 -> FCX – Freeport-McMoRan Inc. | G23: =C26 -> AIR – Airbus SE | H23: =C27 -> BTI – British American Tobacco plc | I23: =C28 -> BHP – BHP Group Ltd. | J23: =C29 -> 0
B24: longeq | C24: XOM – Exxon Mobil Corporation | D24: =ISNUMBER(LEFT(C24,4)+1-1) -> FALSE | E24: =IF(D24,LEFT(C24,10),E23)+1-1 -> 45996 | F24: =C26 -> AIR – Airbus SE | G24: =C27 -> BTI – British American Tobacco plc | H24: =C28 -> BHP – BHP Group Ltd. | I24: =C29 -> 0 | J24: =C30 -> Prev days return S&P500 +0.30%
B25: longeq | C25: FCX – Freeport-McMoRan Inc. | D25: =ISNUMBER(LEFT(C25,4)+1-1) -> FALSE | E25: =IF(D25,LEFT(C25,10),E24)+1-1 -> 45996 | F25: =C27 -> BTI – British American Tobacco plc | G25: =C28 -> BHP – BHP Group Ltd. | H25: =C29 -> 0 | I25: =C30 -> Prev days return S&P500 +0.30% | J25: =C31 -> 0
B26: longeq | C26: AIR – Airbus SE | D26: =ISNUMBER(LEFT(C26,4)+1-1) -> FALSE | E26: =IF(D26,LEFT(C26,10),E25)+1-1 -> 45996 | F26: =C28 -> BHP – BHP Group Ltd. | G26: =C29 -> 0 | H26: =C30 -> Prev days return S&P500 +0.30% | I26: =C31 -> 0 | J26: =C32 -> I've changed the task. please run the task as if it would run tomorrow
B27: longeq | C27: BTI – British American Tobacco plc | D27: =ISNUMBER(LEFT(C27,4)+1-1) -> FALSE | E27: =IF(D27,LEFT(C27,10),E26)+1-1 -> 45996 | F27: =C29 -> 0 | G27: =C30 -> Prev days return S&P500 +0.30% | H27: =C31 -> 0 | I27: =C32 -> I've changed the task. please run the task as if it would run tomorrow | J27: =C33 -> 0
B28: longeq | C28: BHP – BHP Group Ltd. | D28: =ISNUMBER(LEFT(C28,4)+1-1) -> FALSE | E28: =IF(D28,LEFT(C28,10),E27)+1-1 -> 45996 | F28: =C30 -> Prev days return S&P500 +0.30% | G28: =C31 -> 0 | H28: =C32 -> I've changed the task. please run the task as if it would run tomorrow | I28: =C33 -> 0 | J28: =C34 -> 2025-12-05 / 09:00 - Friday
B29: longeq | D29: =ISNUMBER(LEFT(C29,4)+1-1) -> FALSE | E29: =IF(D29,LEFT(C29,10),E28)+1-1 -> 45996 | F29: =C31 -> 0 | G29: =C32 -> I've changed the task. please run the task as if it would run tomorrow | H29: =C33 -> 0 | I29: =C34 -> 2025-12-05 / 09:00 - Friday | J29: =C35 -> 0
B30: longeq | C30: Prev days return S&P500 +0.30% | D30: =ISNUMBER(LEFT(C30,4)+1-1) -> FALSE | E30: =IF(D30,LEFT(C30,10),E29)+1-1 -> 45996 | F30: =C32 -> I've changed the task. please run the task as if it would run tomorrow | G30: =C33 -> 0 | H30: =C34 -> 2025-12-05 / 09:00 - Friday | I30: =C35 -> 0 | J30: =C36 -> Recs:
B31: longeq | D31: =ISNUMBER(LEFT(C31,4)+1-1) -> FALSE | E31: =IF(D31,LEFT(C31,10),E30)+1-1 -> 45996 | F31: =C33 -> 0 | G31: =C34 -> 2025-12-05 / 09:00 - Friday | H31: =C35 -> 0 | I31: =C36 -> Recs: | J31: =C37 -> XOM – Exxon Mobil Corporation
B32: longeq | C32: I've changed the task. please run the task as if it would run tomorrow | D32: =ISNUMBER(LEFT(C32,4)+1-1) -> FALSE | E32: =IF(D32,LEFT(C32,10),E31)+1-1 -> 45996 | F32: =C34 -> 2025-12-05 / 09:00 - Friday | G32: =C35 -> 0 | H32: =C36 -> Recs: | I32: =C37 -> XOM – Exxon Mobil Corporation | J32: =C38 -> FCX – Freeport-McMoRan Inc.
B33: longeq | D33: =ISNUMBER(LEFT(C33,4)+1-1) -> FALSE | E33: =IF(D33,LEFT(C33,10),E32)+1-1 -> 45996 | F33: =C35 -> 0 | G33: =C36 -> Recs: | H33: =C37 -> XOM – Exxon Mobil Corporation | I33: =C38 -> FCX – Freeport-McMoRan Inc. | J33: =C39 -> AIR – Airbus SE
B34: longeq | C34: 2025-12-05 / 09:00 - Friday | D34: =ISNUMBER(LEFT(C34,4)+1-1) -> TRUE | E34: =IF(D34,LEFT(C34,10),E33)+1-1 -> 45996 | F34: =C36 -> Recs: | G34: =C37 -> XOM – Exxon Mobil Corporation | H34: =C38 -> FCX – Freeport-McMoRan Inc. | I34: =C39 -> AIR – Airbus SE | J34: =C40 -> BTI – British American Tobacco plc
B35: longeq | D35: =ISNUMBER(LEFT(C35,4)+1-1) -> FALSE | E35: =IF(D35,LEFT(C35,10),E34)+1-1 -> 45996 | F35: =C37 -> XOM – Exxon Mobil Corporation | G35: =C38 -> FCX – Freeport-McMoRan Inc. | H35: =C39 -> AIR – Airbus SE | I35: =C40 -> BTI – British American Tobacco plc | J35: =C41 -> BHP – BHP Group Ltd.
B36: longeq | C36: Recs: | D36: =ISNUMBER(LEFT(C36,4)+1-1) -> FALSE | E36: =IF(D36,LEFT(C36,10),E35)+1-1 -> 45996 | F36: =C38 -> FCX – Freeport-McMoRan Inc. | G36: =C39 -> AIR – Airbus SE | H36: =C40 -> BTI – British American Tobacco plc | I36: =C41 -> BHP – BHP Group Ltd. | J36: =C42 -> 0
B37: longeq | C37: XOM – Exxon Mobil Corporation | D37: =ISNUMBER(LEFT(C37,4)+1-1) -> FALSE | E37: =IF(D37,LEFT(C37,10),E36)+1-1 -> 45996 | F37: =C39 -> AIR – Airbus SE | G37: =C40 -> BTI – British American Tobacco plc | H37: =C41 -> BHP – BHP Group Ltd. | I37: =C42 -> 0 | J37: =C43 -> Prev days return S&P500 +0.30%
B38: longeq | C38: FCX – Freeport-McMoRan Inc. | D38: =ISNUMBER(LEFT(C38,4)+1-1) -> FALSE | E38: =IF(D38,LEFT(C38,10),E37)+1-1 -> 45996 | F38: =C40 -> BTI – British American Tobacco plc | G38: =C41 -> BHP – BHP Group Ltd. | H38: =C42 -> 0 | I38: =C43 -> Prev days return S&P500 +0.30% | J38: =C44 -> 0
B39: longeq | C39: AIR – Airbus SE | D39: =ISNUMBER(LEFT(C39,4)+1-1) -> FALSE | E39: =IF(D39,LEFT(C39,10),E38)+1-1 -> 45996 | F39: =C41 -> BHP – BHP Group Ltd. | G39: =C42 -> 0 | H39: =C43 -> Prev days return S&P500 +0.30% | I39: =C44 -> 0 | J39: =C45 -> I have changed the task to include prev. days returns. can't you see it?
B40: longeq | C40: BTI – British American Tobacco plc | D40: =ISNUMBER(LEFT(C40,4)+1-1) -> FALSE | E40: =IF(D40,LEFT(C40,10),E39)+1-1 -> 45996 | F40: =C42 -> 0 | G40: =C43 -> Prev days return S&P500 +0.30% | H40: =C44 -> 0 | I40: =C45 -> I have changed the task to include prev. days returns. can't you see it? | J40: =C46 -> 0
...
